Workbook

Sheet Manhole Data
A1: Type III according to standard details — Depth: 1.5-2m ; normal | B1: nr | C1: 1853.832 | D1: 887.31769 | E1: =AVERAGE(C1:D1) -> 1370.5748
A2: Type III according to standard details — Depth: 2-2.5m ; normal | B2: nr | C2: 2100.139 | D2: 1028.8742 | E2: =AVERAGE(C2:D2) -> 1564.5066
A3: Type III according to standard details — Depth: 2.5-3m ; normal | B3: nr | C3: 2356.489 | D3: 1171.5816 | E3: =AVERAGE(C3:D3) -> 1764.0353
A4: Type III according to standard details — Depth: 3-3.5m ; normal | B4: nr | C4: 2663.851 | D4: 1313.1381 | E4: =AVERAGE(C4:D4) -> 1988.4946
A5: Type III according to standard details — Depth: 3.5-4m ; normal | B5: nr | C5: 2959.722 | D5: 1455.8455 | E5: =AVERAGE(C5:D5) -> 2207.7837
A6: Type III according to standard details — Depth: 4-4.5m ; normal | B6: nr | C6: 3707.016 | D6: 1692.9239 | E6: =AVERAGE(C6:D6) -> 2699.9699
A7: Type III according to standard details — Depth: 4.5-5m ; normal | B7: nr | C7: 4166.746 | D7: 1818.36 | E7: =AVERAGE(C7:D7) -> 2992.553
A8: Type III according to standard details — Depth: 5-5.5m ; normal | B8: nr | C8: 4639.419 | D8: 1943.8127 | E8: =AVERAGE(C8:D8) -> 3291.6158
A9: Type III according to standard details — Depth: 5.5-6m ; normal | B9: nr | C9: 5028.108 | D9: 2068.1062 | E9: =AVERAGE(C9:D9) -> 3548.1071
A10: Type III according to standard details — Depth: 6-6.5m ; normal | B10: nr | C10: 5535.526 | D10: 2193.5506 | E10: =AVERAGE(C10:D10) -> 3864.5383
A11: Type III according to standard details — Depth: 6.5-7m ; normal | B11: nr | C11: 5893.505 | D11: 2375.59 | E11: =AVERAGE(C11:D11) -> 4134.5475
A12: Type III according to standard details — Depth: 7-7.5m ; normal | B12: nr | C12: 6250.759 | D12: 2531.9052 | E12: =AVERAGE(C12:D12) -> 4391.3321
... A37: Type IIb according to standard details — Depth: 9.5-10m ; normal | B37: nr | C37: 6392.043 | D37: 8056.062 | E37: =AVERAGE(C37:D37) -> 7224.0525

Sheet Pipe Data
A1: Dia (mm) | B1: Source | C1: Up to 1.5 | D1: 1.5 - 2.0 | E1: 2.0 - 2.5 | F1: 2.5 - 3.0 | G1: 3.0 - 3.5 | H1: 3.5 - 4.0 | I1: 4.0 - 4.5 | J1: 4.5 - 5.0 | K1: 5.0 - 5.5 | L1: 5.5 - 6.0 | M1: 6.0 - 6.5 | N1: 6.5 - 7.0 | O1: 7.0 - 7.5 | P1: 7.5 - 8.0 | Q1: 8.0 - 8.5 | R1: 8.5 - 9.0 | S1: 9.0 - 9.5 | T1: 9.5 - 10.0
A2: 200 | B2: Target | C2: 12.653 | D2: 14.136 | E2: 16.094 | F2: 18.994 | G2: 23.268 | H2: 28.13 | I2: 35.046 | J2: 56.098 | K2: 68.229 | L2: 84.87 | M2: 104.38 | N2: 129.756 | O2: 164.242 | P2: =O2/N2*O2 -> 207.89354 | Q2: =P2/O2*P2 -> 263.14661 | R2: =Q2/P2*Q2 -> 333.0846 | S2: =R2/Q2*R2 -> 421.61041 | T2: =S2/R2*S2 -> 533.66424
B3: HA | C3: 8.8801588 | D3: 10.007357 | E3: 10.852756 | F3: 11.923595 | G3: 13.107153 | H3: 15.605352 | I3: 16.73255 | J3: 18.423348 | K3: 20.114146 | L3: 26.654528 | M3: 29.212008 | N3: 35.605708 | O3: 40.720668 | P3: =O3/N3*O3 -> 46.570421 | Q3: =P3/O3*P3 -> 53.260524 | R3: =Q3/P3*Q3 -> 60.911697 | S3: =R3/Q3*R3 -> 69.662005 | T3: =S3/R3*S3 -> 79.669343
B4: Concord | C4: 9.875 | D4: 11.237 | E4: 12.824 | F4: 14.468 | G4: 16.112 | H4: 18.424 | I4: 20.3 | J4: 22.233 | K4: 19.824 | L4: 21.236 | M4: 22.793 | N4: 24.386 | O4: 25.979 | P4: 27.572 | Q4: =P4/O4*P4 -> 29.262681 | R4: =Q4/P4*Q4 -> 31.057032 | S4: =R4/Q4*R4 -> 32.961411 | T4: =S4/R4*S4 -> 34.982563
A5: 250 | B5: Target | C5: =C2/D2*D5 -> 16.137588 | D5: 18.029 | E5: 20.08 | F5: 23.074 | G5: 27.463 | H5: 34.084 | I5: 40.089 | J5: 61.303 | K5: 73.617 | L5: 90.51 | M5: =L5/K5*L5 -> 111.27946 | N5: =M5/L5*M5 -> 136.81492 | O5: =N5/M5*N5 -> 168.21004 | P5: =O5/N5*O5 -> 206.80944 | Q5: =P5/O5*P5 -> 254.26631 | R5: =Q5/P5*Q5 -> 312.61316 | S5: =R5/Q5*R5 -> 384.34896 | T5: =S5/R5*S5 -> 472.54608
B6: HA | C6: =C3/D3*D6 -> 10.764963 | D6: 12.131409 | E6: 13.258607 | F6: 14.385806 | G6: 15.513004 | H6: 17.64342 | I6: 19.041146 | J6: 20.731944 | K6: 22.140942 | L6: 24.11354 | M6: =L6/K6*L6 -> 26.261881 | N6: =M6/L6*M6 -> 28.601624 | O6: =N6/M6*N6 -> 31.149822 | P6: =O6/N6*O6 -> 33.925045 | Q6: =P6/O6*P6 -> 36.94752 | R6: =Q6/P6*Q6 -> 40.239276 | S6: =R6/Q6*R6 -> 43.824304 | T6: =S6/R6*S6 -> 47.728732
B7: Concord | C7: =C4/D4*D7 -> 12.200287 | D7: 13.883 | E7: 15.592 | F7: 17.361 | G7: 19.131 | H7: 22.004 | I7: 24.022 | J7: 26.103 | K7: 23.511 | L7: 25.031 | M7: 26.707 | N7: 28.422 | O7: 30.136 | P7: 31.851 | Q7: =P7/O7*P7 -> 33.663598 | R7: =Q7/P7*Q7 -> 35.579349 | S7: =R7/Q7*R7 -> 37.604123 | T7: =S7/R7*S7 -> 39.744124
A8: 300 | B8: Target | C8: =C5/D5*D8 -> 20.840393 | D8: 23.283 | E8: 25.428 | F8: 28.517 | G8: 33.02 | H8: 38.073 | I8: 45.54 | J8: 66.958 | K8: 79.498 | L8: =K8/J8*K8 -> 94.386511 | M8: =L8/K8*L8 -> 112.06337 | N8: =M8/L8*M8 -> 133.05077 | O8: =N8/M8*N8 -> 157.96873 | P8: =O8/N8*O8 -> 187.55336 | Q8: =P8/O8*P8 -> 222.67865 | R8: =Q8/P8*Q8 -> 264.38226 | S8: =R8/Q8*R8 -> 313.89619 | T8: =S8/R8*S8 -> 372.68316
B9: HA | C9: =C6/D6*D9 -> 22.386801 | D9: 25.228458 | E9: 26.817808 | F9: 28.880582 | G9: 30.548835 | H9: 36.312305 | I9: 42.255516 | J9: 46.053374 | K9: 48.316744 | L9: =K9/J9*K9 -> 50.69135 | M9: =L9/K9*L9 -> 53.182661 | N9: =M9/L9*M9 -> 55.796412 | O9: =N9/M9*N9 -> 58.53862 | P9: =O9/N9*O9 -> 61.415598 | Q9: =P9/O9*P9 -> 64.433969 | R9: =Q9/P9*Q9 -> 67.600684 | S9: =R9/Q9*R9 -> 70.923033 | T9: =S9/R9*S9 -> 74.408663
B10: Concord | C10: =C7/D7*D10 -> 17.433501 | D10: 19.838 | E10: 21.519 | F10: 23.26 | G10: 25 | H10: 28.054 | I10: 30.04 | J10: 32.086 | K10: 29.536 | L10: 31.031 | M10: 32.68 | N10: 34.367 | O10: 36.053 | P10: 37.74 | Q10: =P10/O10*P10 -> 39.505938 | R10: =Q10/P10*Q10 -> 41.354509 | S10: =R10/Q10*R10 -> 43.289579 | T10: =S10/R10*S10 -> 45.315194
A11: 350 | B11: Target | C11: =C8/D8*D11 -> 25.045529 | D11: 27.981 | E11: 30.219 | F11: 33.404 | G11: 38.02 | H11: 46.577 | I11: 52.779 | J11: 74.414 | K11: 87.192 | L11: 104.687 | M11: =L11/K11*L11 -> 125.69236 | N11: =M11/L11*M11 -> 150.91242 | O11: =N11/M11*N11 -> 181.19287 | P11: =O11/N11*O11 -> 217.54906 | Q11: =P11/O11*P11 -> 261.20009 | R11: =Q11/P11*Q11 -> 313.60967 | S11: =R11/Q11*R11 -> 376.53518 | T11: =S11/R11*S11 -> 452.08664
B12: HA | C12: =C9/D9*D12 -> 28.860731 | D12: 32.524154 | E12: 34.677103 | F12: 35.797012 | G12: 36.424261 | H12: 40.361404 | I12: 42.210009 | J12: 45.557789 | K12: 47.55293 | L12: 64.163118 | M12: =L12/K12*L12 -> 86.575227 | N12: =M12/L12*M12 -> 116.81586 | O12: =N12/M12*N12 -> 157.61952 | P12: =O12/N12*O12 -> 212.67585 | Q12: =P12/O12*P12 -> 286.96329 | R12: =Q12/P12*Q12 -> 387.19927 | S12: =R12/Q12*R12 -> 522.44756 | T12: =S12/R12*S12 -> 704.93793
B13: Concord | C13: =C10/D10*D13 -> 23.103475 | D13: 26.29 | E13: 28.064 | F13: 29.901 | G13: 31.738 | H13: 36.434 | I13: 38.529 | J13: 40.69 | K13: 37.998 | L13: 39.576 | M13: 41.316 | N13: 43.097 | O13: 44.877 | P13: 46.658 | Q13: =P13/O13*P13 -> 48.509681 | R13: =Q13/P13*Q13 -> 50.434849 | S13: =R13/Q13*R13 -> 52.436419 | T13: =S13/R13*S13 -> 54.517424
A14: 400 | B14: Target | C14: =C11/D11*D14 -> 29.558349 | D14: =D11/E11*E14 -> 33.022747 | E14: 35.664 | F14: 38.943 | G14: 43.673 | H14: 51.644 | I14: 57.944 | J14: 79.724 | K14: 92.669 | L14: 110.399 | M14: =L14/K14*L14 -> 131.52121 | N14: =M14/L14*M14 -> 156.68465 | O14: =N14/M14*N14 -> 186.66252 | P14: =O14/N14*O14 -> 222.37594 | Q14: =P14/O14*P14 -> 264.92226 | R14: =Q14/P14*Q14 -> 315.60881 | S14: =R14/Q14*R14 -> 375.99302 | T14: =S14/R14*S14 -> 447.9303
B15: HA | C15: =C12/D12*D15 -> 27.669301 | D15: =D12/E12*E15 -> 31.18149 | E15: 33.245561 | F15: 35.499958 | G15: 37.269659 | H15: 41.342066 | I15: 43.269576 | J15: 46.775163 | K15: 48.871752 | L15: 51.148693 | M15: =L15/K15*L15 -> 53.531717 | N15: =M15/L15*M15 -> 56.025766 | O15: =N15/M15*N15 -> 58.636014 | P15: =O15/N15*O15 -> 61.367873 | Q15: =P15/O15*P15 -> 64.22701 | R15: =Q15/P15*Q15 -> 67.219354 | S15: =R15/Q15*R15 -> 70.351112 | T15: =S15/R15*S15 -> 73.628779
B16: Concord | C16: =C13/D13*D16 -> 23.146424 | D16: =D13/E13*E16 -> 26.338872 | E16: =E13/F13*F16 -> 28.11617 | F16: =F13/G13*G16 -> 29.956585 | G16: 31.797 | H16: 36.163 | I16: 38.369 | J16: 40.643 | K16: 37.81 | L16: 39.471 | M16: 41.303 | N16: 43.177 | O16: 45.051 | P16: 46.925 | Q16: =P16/O16*P16 -> 48.876953 | R16: =Q16/P16*Q16 -> 50.910103 | S16: =R16/Q16*R16 -> 53.027826 | T16: =S16/R16*S16 -> 55.23364
A17: 450 | B17: Target | C17: =C14/D14*D17 -> 33.641021 | D17: =D14/E14*E17 -> 37.58393 | E17: 40.59 | F17: 44.487 | G17: 49.332 | H17: 54.671 | I17: 65.16 | J17: 87.204 | K17: =J17/I17*J17 -> 116.70561 | L17: =K17/J17*K17 -> 156.18779 | M17: =L17/K17*L17 -> 209.02701 | N17: =M17/L17*M17 -> 279.74203 | O17: =N17/M17*N17 -> 374.38036 | P17: =O17/N17*O17 -> 501.03538 | Q17: =P17/O17*P17 -> 670.5385 | R17: =Q17/P17*Q17 -> 897.38551 | ... T17: =S17/R17*S17 -> 1607.2732
B18: HA | C18: =C15/D15*D18 -> 38.96734 | D18: =D15/E15*E18 -> 43.91364 | E18: 46.82052 | F18: 49.378 | G18: 51.93548 | H18: 63.720697 | I18: 70.114397 | J18: 76.508097 | K18: =J18/I18*J18 -> 83.484836 | L18: =K18/J18*K18 -> 91.09778 | M18: =L18/K18*L18 -> 99.404945 | N18: =M18/L18*M18 -> 108.46964 | O18: =N18/M18*N18 -> 118.36093 | P18: =O18/N18*O18 -> 129.15421 | Q18: =P18/O18*P18 -> 140.93173 | R18: =Q18/P18*Q18 -> 153.78323 | ... T18: =S18/R18*S18 -> 183.10886
B19: Concord | C19: =C16/D16*D19 -> 29.352708 | D19: =D16/E16*E19 -> 33.401153 | E19: 35.655 | F19: 37.686 | G19: 46.624 | H19: 48.655 | I19: =H19/G19*H19 -> 50.774473 | J19: =I19/H19*I19 -> 52.986273 | K19: =J19/I19*J19 -> 55.294421 | L19: =K19/J19*K19 -> 57.703116 | M19: =L19/K19*L19 -> 60.216736 | N19: =M19/L19*M19 -> 62.839853 | O19: =N19/M19*N19 -> 65.577236 | P19: =O19/N19*O19 -> 68.433862 | ... T19: =S19/R19*S19 -> 81.16015
A20: 500 | B20: Target | C20: =C17/D17*D20 -> 39.856592 | D20: 44.528 | E20: 47.048 | F20: 50.516 | G20: 55.476 | H20: 60.91 | I20: 76.951 | J20: 99.14 | K20: 112.538 | L20: 130.857 | M20: 152.128 | N20: 180.317 | O20: =N20/M20*N20 -> 213.72936 | P20: =O20/N20*O20 -> 253.33297 | Q20: =P20/O20*P20 -> 300.27503 | R20: =Q20/P20*Q20 -> 355.91537 | S20: =R20/Q20*R20 -> 421.86574 | T20: =S20/R20*S20 -> 500.03658
B21: HA | C21: =C18/D18*D21 -> 34.932756 | D21: 39.366927 | E21: 41.283165 | F21: 43.763002 | G21: 44.26304 | H21: 49.406065 | I21: 52.393141 | J21: 54.523546 | K21: 58.389837 | L21: 62.932447 | M21: 89.295497 | N21: 95.689197 | O21: =N21/M21*N21 -> 102.5407 | P21: =O21/N21*O21 -> 109.88277 | Q21: =P21/O21*P21 -> 117.75056 | R21: =Q21/P21*Q21 -> 126.18168 | S21: =R21/Q21*R21 -> 135.21649 | T21: =S21/R21*S21 -> 144.89821
B22: Concord | C22: =C19/D19*D22 -> 29.939608 | D22: 34.069 | E22: 36.123 | F22: 38.25 | G22: 40.377 | H22: 49.413 | I22: 51.84 | J22: 54.341 | K22: 51.224 | L22: 53.052 | M22: 55.067 | N22: 57.128 | O22: 59.19 | P22: 61.251 | Q22: =P22/O22*P22 -> 63.383764 | R22: =Q22/P22*Q22 -> 65.590791 | S22: =R22/Q22*R22 -> 67.874667 | T22: =S22/R22*S22 -> 70.238068
A23: 600 | B23: Target | C23: =C20/D20*D23 -> 50.193143 | D23: =D20/E20*E23 -> 56.076051 | E23: =E20/F20*F23 -> 59.249596 | F23: 63.617 | G23: 68.805 | H23: 81.247 | I23: 87.941 | J23: 110.473 | K23: 124.257 | L23: 143.1 | M23: 157.658 | N23: 193.15 | O23: 231.353 | P23: 286.66 | Q23: =P23/O23*P23 -> 355.18863 | R23: =Q23/P23*Q23 -> 440.09965 | S23: =R23/Q23*R23 -> 545.30939 | T23: =S23/R23*S23 -> 675.67047
B24: HA | C24: =C21/D21*D24 -> 46.88391 | D24: =D21/E21*E24 -> 52.835096 | E24: =E21/F21*F24 -> 55.406914 | F24: 58.73515 | G24: 61.338979 | H24: 69.786558 | I24: 72.559466 | J24: 77.5755 | K24: 80.573848 | L24: 83.20022 | M24: 90.842626 | N24: 98.733016 | O24: 105.49621 | P24: 138.8603 | Q24: =P24/O24*P24 -> 182.77609 | R24: =Q24/P24*Q24 -> 240.58062 | S24: =R24/Q24*R24 -> 316.66635 | T24: =S24/R24*S24 -> 416.81485
B25: Concord | C25: =C22/D22*D25 -> 36.985787 | D25: =D22/E22*E25 -> 42.087017 | E25: =E22/F22*F25 -> 44.624418 | F25: 47.252 | G25: 49.573 | H25: 59.069 | I25: 61.716 | J25: 64.445 | K25: 61.045 | L25: 63.039 | M25: 65.237 | N25: 67.486 | O25: 69.735 | P25: 71.984 | Q25: =P25/O25*P25 -> 74.305532 | R25: =Q25/P25*Q25 -> 76.701934 | S25: =R25/Q25*R25 -> 79.175623 | T25: =S25/R25*S25 -> 81.729089
A26: 700 | B26: Target | C26: =C23/D23*D26 -> 64.627183 | D26: =D23/E23*E26 -> 72.201838 | E26: 76.288 | F26: 80.135 | G26: 85.551 | H26: 105.001 | I26: 111.892 | J26: 134.805 | K26: 149.015 | L26: 168.422 | M26: 190.833 | N26: 219.787 | O26: 258.931 | P26: 315.558 | Q26: 354.018 | R26: 441.217 | S26: 479.116 | T26: =S26/R26*S26 -> 520.27039
B27: HA | C27: =C24/D24*D27 -> 57.354312 | D27: =D24/E24*E27 -> 64.634552 | E27: 67.780725 | F27: 70.542361 | G27: 75.294797 | H27: 86.349483 | I27: 89.280199 | J27: 94.578032 | K27: 97.734187 | L27: 123.08562 | M27: 148.66042 | N27: 172.95648 | O27: 212.59742 | P27: 314.89662 | Q27: 378.83362 | R27: 442.77062 | S27: 506.70762 | T27: =S27/R27*S27 -> 579.87726
B28: Concord | C28: =C25/D25*D28 -> 55.987887 | D28: =D25/E25*E28 -> 63.709964 | E28: 67.551 | F28: 70.065 | G28: 72.579 | H28: 75.093 | I28: 77.961 | J28: 80.917 | K28: 77.233 | L28: 79.393 | M28: 81.774 | N28: 84.211 | O28: 86.647 | P28: 89.084 | Q28: 91.744 | R28: 94.46 | S28: 97.176 | T28: =S28/R28*S28 -> 99.970093
A29: 800 | B29: Target | C29: =C26/D26*D29 -> 96.319815 | D29: =D26/E26*E29 -> 107.60902 | E29: 113.699 | F29: 117.735 | G29: 123.38 | H29: 143.021 | I29: 150.108 | J29: 173.494 | K29: 188.22 | L29: 208.279 | M29: 231.371 | N29: 261.141 | O29: =N29/M29*N29 -> 294.74144 | P29: =O29/N29*O29 -> 332.66518 | Q29: =P29/O29*P29 -> 375.46848 | R29: =Q29/P29*Q29 -> 423.77918 | S29: =R29/Q29*R29 -> 478.30592 | T29: =S29/R29*S29 -> 539.8485
B30: HA | C30: =C27/D27*D30 -> 91.797962 | D30: =D27/E27*E30 -> 103.45029 | E30: 108.48587 | F30: 117.43705 | G30: 130.22445 | H30: 146.84807 | I30: 162.19295 | J30: 174.98035 | K30: 187.76775 | L30: 213.34255 | M30: 238.91735 | N30: 251.70475 | O30: =N30/M30*N30 -> 265.17656 | P30: =O30/N30*O30 -> 279.36941 | Q30: =P30/O30*P30 -> 294.3219 | R30: =Q30/P30*Q30 -> 310.07468 | S30: =R30/Q30*R30 -> 326.67058 | T30: =S30/R30*S30 -> 344.15473
B31: Concord | C31: =C28/D28*D31 -> 68.572751 | D31: =D28/E28*E31 -> 78.030582 | E31: 82.735 | F31: 85.442 | G31: 88.149 | H31: 115.497 | I31: 118.586 | J31: 121.77 | K31: 117.803 | L31: 120.129 | M31: 122.693 | N31: 125.317 | O31: =N31/M31*N31 -> 127.99712 | P31: =O31/N31*O31 -> 130.73456 | Q31: =P31/O31*P31 -> 133.53054 | R31: =Q31/P31*Q31 -> 136.38632 | S31: =R31/Q31*R31 -> 139.30317 | T31: =S31/R31*S31 -> 142.28241
A32: 900 | B32: Target | C32: =C29/D29*D32 -> 125.14749 | D32: =D29/E29*E32 -> 139.81545 | E32: =E29/F29*F32 -> 147.72811 | F32: =F29/G29*G32 -> 152.97205 | G32: =G29/H29*H32 -> 160.30655 | H32: =H29/I29*I32 -> 185.82592 | I32: 195.034 | J32: 218.859 | K32: 234.068 | L32: 254.747 | M32: 278.486 | N32: 309.038 | O32: 350.212 | P32: 398.445 | Q32: 437.304 | R32: 524.836 | S32: 587.107 | T32: 630.879
B33: HA | C33: =C30/D30*D33 -> 99.972664 | D33: =D30/E30*E33 -> 112.66264 | E33: =E30/F30*F33 -> 118.14665 | F33: =F30/G30*G33 -> 127.89494 | G33: =G30/H30*H33 -> 141.82107 | H33: =H30/I30*I33 -> 159.92504 | I33: 176.6364 | J33: =J30/K30*K33 -> 188.44017 | K33: 202.2112 | L33: 227.786 | M33: 253.3608 | N33: 266.1482 | O33: 291.723 | P33: 342.8726 | Q33: 406.8096 | R33: 445.1718 | S33: 470.7466 | T33: 496.3214
B34: Concord | C34: =C31/D31*D34 -> 69.570042 | D34: =D31/E31*E34 -> 79.165424 | E34: =E31/F31*F34 -> 83.938261 | F34: =F31/G31*G34 -> 86.684631 | G34: 89.431 | H34: 116.972 | I34: 120.281 | J34: 123.692 | K34: 119.442 | L34: 121.934 | M34: 124.682 | N34: 127.493 | O34: 130.304 | P34: 133.115 | Q34: 136.185 | R34: 139.318 | S34: 142.452 | T34: =S34/R34*S34 -> 145.6565
A35: 1000 | B35: Target | C35: =C32/C29*C32 -> 162.60302 | D35: =D32/D29*D32 -> 181.66098 | E35: =E32/E29*E32 -> 191.94183 | F35: =F32/F29*F32 -> 198.75523 | G35: =G32/G29*G32 -> 208.28488 | H35: =H32/H29*H32 -> 241.44198 | I35: =I32/I29*I32 -> 253.40596 | J35: =J32/J29*J32 -> 276.08598 | ... T35: =T32/T29*T32 -> 737.25927
B36: HA | C36: =C33/C30*C33 -> 108.87533 | D36: =D33/D30*D33 -> 122.69537 | E36: =E33/E30*E33 -> 128.66773 | F36: =F33/F30*F33 -> 139.28412 | G36: =G33/G30*G33 -> 154.45038 | H36: =H33/H30*H33 -> 174.16653 | I36: =I33/I30*I33 -> 192.36605 | J36: =J33/J30*J33 -> 202.93534 | ... T36: =T33/T30*T33 -> 715.76796
B37: Concord | C37: =C34/C31*C34 -> 70.581838 | D37: =D34/D31*D34 -> 80.316771 | E37: =E34/E31*E34 -> 85.159022 | F37: =F34/F31*F34 -> 87.945333 | G37: =G34/G31*G34 -> 90.731645 | H37: =H34/H31*H34 -> 118.46584 | I37: =I34/I31*I34 -> 122.00023 | J37: =J34/J31*J34 -> 125.64434 | ... T37: =T34/T31*T34 -> 149.1106

Sheet Pipe Rate
A1: Sewer Pipes | B1: Up to 1.5 | C1: 1.5 - 2.0 | D1: 2.0 - 2.5 | E1: 2.5 - 3.0 | F1: 3.0 - 3.5 | G1: 3.5 - 4.0 | H1: 4.0 - 4.5 | I1: 4.5 - 5.0 | J1: 5.0 - 5.5 | K1: 5.5 - 6.0 | L1: 6.0 - 6.5 | M1: 6.5 - 7.0 | N1: 7.0 - 7.5 | O1: 7.5 - 8.0 | P1: 8.0 - 8.5 | Q1: 8.5 - 9.0 | R1: 9.0 - 9.5 | S1: 9.5 - 10.0 | T1: 10.0 - 10.5 | U1: 10.5 - 11.0 | V1: 11.0 - 11.5 | W1: 11.5 - 12.0 | X1: 12.0 - 12.5 | Y1: 12.5 - 13.0 | Z1: 13.0 - 13.5 | AA1: 13.5 - 14.0 | AB1: 14.0 - 14.5 | AC1: 14.5 - 15.0
A2: 200 | B2: 10.5 | C2: =B2*C$26 -> 11.655 | D2: =C2*D$26 -> 12.93705 | E2: =D2*E$26 -> 14.360126 | F2: =E2*F$26 -> 15.939739 | G2: =F2*G$26 -> 17.693111 | H2: =G2*H$26 -> 19.639353 | I2: =H2*I$26 -> 21.799682 | J2: =I2*J$26 -> 24.197647 | ... AC2: =AB2*AC$26 -> 282.33898
A3: 250 | B3: 13 | C3: =B3*C$26 -> 14.43 | D3: =C3*D$26 -> 16.0173 | E3: =D3*E$26 -> 17.779203 | F3: =E3*F$26 -> 19.734915 | G3: =F3*G$26 -> 21.905756 | H3: =G3*H$26 -> 24.315389 | I3: =H3*I$26 -> 26.990082 | J3: =I3*J$26 -> 29.958991 | ... AC3: =AB3*AC$26 -> 349.56255
A4: 280 | B4: 16.6 | C4: =B4*C$26 -> 18.426 | D4: =C4*D$26 -> 20.45286 | E4: =D4*E$26 -> 22.702675 | F4: =E4*F$26 -> 25.199969 | G4: =F4*G$26 -> 27.971965 | H4: =G4*H$26 -> 31.048882 | I4: =H4*I$26 -> 34.464259 | J4: =I4*J$26 -> 38.255327 | ... AC4: =AB4*AC$26 -> 446.36449
A5: 315 | B5: 21.2 | C5: =B5*C$26 -> 23.532 | D5: =C5*D$26 -> 26.12052 | E5: =D5*E$26 -> 28.993777 | F5: =E5*F$26 -> 32.183093 | G5: =F5*G$26 -> 35.723233 | H5: =G5*H$26 -> 39.652789 | I5: =H5*I$26 -> 44.014595 | J5: =I5*J$26 -> 48.856201 | ... AC5: =AB5*AC$26 -> 570.05585
A6: 355 | B6: 25.7 | C6: =B6*C$26 -> 28.527 | D6: =C6*D$26 -> 31.66497 | E6: =D6*E$26 -> 35.148117 | F6: =E6*F$26 -> 39.01441 | G6: =F6*G$26 -> 43.305995 | H6: =G6*H$26 -> 48.069654 | I6: =H6*I$26 -> 53.357316 | J6: =I6*J$26 -> 59.226621 | ... AC6: =AB6*AC$26 -> 691.05827
A7: 400 | B7: 26.8 | C7: =B7*C$26 -> 29.748 | D7: =C7*D$26 -> 33.02028 | E7: =D7*E$26 -> 36.652511 | F7: =E7*F$26 -> 40.684287 | G7: =F7*G$26 -> 45.159559 | H7: =G7*H$26 -> 50.12711 | I7: =H7*I$26 -> 55.641092 | J7: =I7*J$26 -> 61.761612 | ... AC7: =AB7*AC$26 -> 720.63664
A8: 450 | B8: 34 | C8: =B8*C$26 -> 37.74 | D8: =C8*D$26 -> 41.8914 | E8: =D8*E$26 -> 46.499454 | F8: =E8*F$26 -> 51.614394 | G8: =F8*G$26 -> 57.291977 | H8: =G8*H$26 -> 63.594095 | I8: =H8*I$26 -> 70.589445 | J8: =I8*J$26 -> 78.354284 | ... AC8: =AB8*AC$26 -> 914.24052
A9: 500 | B9: 35 | C9: =B9*C$26 -> 38.85 | D9: =C9*D$26 -> 43.1235 | E9: =D9*E$26 -> 47.867085 | F9: =E9*F$26 -> 53.132464 | G9: =F9*G$26 -> 58.977035 | H9: =G9*H$26 -> 65.464509 | I9: =H9*I$26 -> 72.665605 | J9: =I9*J$26 -> 80.658822 | ... AC9: =AB9*AC$26 -> 941.12995
A10: 560 | B10: 40 | C10: =B10*C$26 -> 44.4 | D10: =C10*D$26 -> 49.284 | E10: =D10*E$26 -> 54.70524 | F10: =E10*F$26 -> 60.722816 | G10: =F10*G$26 -> 67.402326 | H10: =G10*H$26 -> 74.816582 | I10: =H10*I$26 -> 83.046406 | J10: =I10*J$26 -> 92.181511 | ... AC10: =AB10*AC$26 -> 1075.5771
A11: 600 | B11: 44.7 | C11: =B11*C$26 -> 49.617 | D11: =C11*D$26 -> 55.07487 | E11: =D11*E$26 -> 61.133106 | F11: =E11*F$26 -> 67.857747 | G11: =F11*G$26 -> 75.3221 | H11: =G11*H$26 -> 83.60753 | I11: =H11*I$26 -> 92.804359 | J11: =I11*J$26 -> 103.01284 | ... AC11: =AB11*AC$26 -> 1201.9574
A12: 630 | B12: 51 | C12: =B12*C$26 -> 56.61 | D12: =C12*D$26 -> 62.8371 | E12: =D12*E$26 -> 69.749181 | F12: =E12*F$26 -> 77.421591 | G12: =F12*G$26 -> 85.937966 | H12: =G12*H$26 -> 95.391142 | I12: =H12*I$26 -> 105.88417 | J12: =I12*J$26 -> 117.53143 | ... AC12: =AB12*AC$26 -> 1371.3608
A13: 710 | B13: 59.3 | C13: =B13*C$26 -> 65.823 | D13: =C13*D$26 -> 73.06353 | E13: =D13*E$26 -> 81.100518 | F13: =E13*F$26 -> 90.021575 | G13: =F13*G$26 -> 99.923949 | H13: =G13*H$26 -> 110.91558 | I13: =H13*I$26 -> 123.1163 | J13: =I13*J$26 -> 136.65909 | ... AC13: =AB13*AC$26 -> 1594.543
... A23: 2200 | B23: 525.3 | C23: =B23*C$26 -> 583.083 | D23: =C23*D$26 -> 647.22213 | E23: =D23*E$26 -> 718.41656 | F23: =E23*F$26 -> 797.44239 | G23: =F23*G$26 -> 885.16105 | H23: =G23*H$26 -> 982.52876 | I23: =H23*I$26 -> 1090.6069 | J23: =I23*J$26 -> 1210.5737 | ... AC23: =AB23*AC$26 -> 14125.016
A25: Depth | B25: Up to 1.5 | C25: 1.5 - 2.0 | D25: 2.0 - 2.5 | E25: 2.5 - 3.0 | F25: 3.0 - 3.5 | G25: 3.5 - 4.0 | H25: 4.0 - 4.5 | I25: 4.5 - 5.0 | J25: 5.0 - 5.5 | K25: 5.5 - 6.0 | L25: 6.0 - 6.5 | M25: 6.5 - 7.0 | N25: 7.0 - 7.5 | O25: 7.5 - 8.0 | P25: 8.0 - 8.5 | Q25: 8.5 - 9.0 | R25: 9.0 - 9.5 | S25: 9.5 - 10.0 | T25: 10.0 - 10.5 | U25: 10.5 - 11.0 | V25: 11.0 - 11.5 | W25: 11.5 - 12.0 | X25: 12.0 - 12.5 | Y25: 12.5 - 13.0 | Z25: 13.0 - 13.5 | AA25: 13.5 - 14.0 | AB25: 14.0 - 14.5 | AC25: 14.5 - 15.0
A26: Growth | C26: 1.11 | D26: 1.11 | E26: 1.11 | F26: 1.11 | G26: 1.11 | H26: 1.11 | I26: 1.11 | J26: 1.11 | K26: 1.11 | L26: 1.3 | M26: 1.11 | N26: 1.11 | O26: 1.11 | P26: 1.11 | Q26: 1.11 | R26: 1.3 | S26: 1.11 | T26: 1.11 | U26: 1.11 | V26: 1.11 | W26: 1.11 | X26: 1.3 | Y26: 1.11 | Z26: 1.11 | AA26: 1.11 | AB26: 1.11 | AC26: 1.11
A29: Force/TSE Pipes | B29: Up to 1.5 | C29: 1.5 - 2.0 | D29: 2.0 - 2.5 | E29: 2.5 - 3.0 | F29: 3.0 - 3.5 | G29: 3.5 - 4.0 | H29: 4.0 - 4.5 | I29: 4.5 - 5.0 | J29: 5.0 - 5.5 | K29: 5.5 - 6.0 | L29: 6.0 - 6.5 | M29: 6.5 - 7.0 | N29: 7.0 - 7.5 | O29: 7.5 - 8.0 | P29: 8.0 - 8.5 | Q29: 8.5 - 9.0 | R29: 9.0 - 9.5 | S29: 9.5 - 10.0 | T29: 10.0 - 10.5 | U29: 10.5 - 11.0 | V29: 11.0 - 11.5 | W29: 11.5 - 12.0
A30: 100 | B30: 10.2 | C30: =B30*C$26 -> 11.322 | D30: =C30*D$26 -> 12.56742 | E30: =D30*E$26 -> 13.949836 | F30: =E30*F$26 -> 15.484318 | G30: =F30*G$26 -> 17.187593 | H30: =G30*H$26 -> 19.078228 | I30: =H30*I$26 -> 21.176834 | J30: =I30*J$26 -> 23.506285 | ... W30: =V30*W$26 -> 125.20552
A31: 110 | B31: 10.2 | C31: =B31*C$26 -> 11.322 | D31: =C31*D$26 -> 12.56742 | E31: =D31*E$26 -> 13.949836 | F31: =E31*F$26 -> 15.484318 | G31: =F31*G$26 -> 17.187593 | H31: =G31*H$26 -> 19.078228 | I31: =H31*I$26 -> 21.176834 | J31: =I31*J$26 -> 23.506285 | ... W31: =V31*W$26 -> 125.20552
A32: 150 | B32: 14 | C32: =B32*C$26 -> 15.54 | D32: =C32*D$26 -> 17.2494 | E32: =D32*E$26 -> 19.146834 | F32: =E32*F$26 -> 21.252986 | G32: =F32*G$26 -> 23.590814 | H32: =G32*H$26 -> 26.185804 | I32: =H32*I$26 -> 29.066242 | J32: =I32*J$26 -> 32.263529 | ... W32: =V32*W$26 -> 171.85071
A33: 180 | B33: 17.4 | C33: =B33*C$26 -> 19.314 | D33: =C33*D$26 -> 21.43854 | E33: =D33*E$26 -> 23.796779 | F33: =E33*F$26 -> 26.414425 | G33: =F33*G$26 -> 29.320012 | H33: =G33*H$26 -> 32.545213 | I33: =H33*I$26 -> 36.125187 | J33: =I33*J$26 -> 40.098957 | ... W33: =V33*W$26 -> 213.58589
A34: 200 | B34: 32.1 | C34: =B34*C$26 -> 35.631 | D34: =C34*D$26 -> 39.55041 | E34: =D34*E$26 -> 43.900955 | F34: =E34*F$26 -> 48.73006 | G34: =F34*G$26 -> 54.090367 | H34: =G34*H$26 -> 60.040307 | I34: =H34*I$26 -> 66.644741 | J34: =I34*J$26 -> 73.975662 | ... W34: =V34*W$26 -> 394.02913
A35: 225 | B35: 25.2 | C35: =B35*C$26 -> 27.972 | D35: =C35*D$26 -> 31.04892 | E35: =D35*E$26 -> 34.464301 | F35: =E35*F$26 -> 38.255374 | G35: =F35*G$26 -> 42.463466 | H35: =G35*H$26 -> 47.134447 | I35: =H35*I$26 -> 52.319236 | J35: =I35*J$26 -> 58.074352 | ... W35: =V35*W$26 -> 309.33128
A36: 250 | B36: 40.7 | C36: =B36*C$26 -> 45.177 | D36: =C36*D$26 -> 50.14647 | E36: =D36*E$26 -> 55.662582 | F36: =E36*F$26 -> 61.785466 | G36: =F36*G$26 -> 68.581867 | H36: =G36*H$26 -> 76.125872 | I36: =H36*I$26 -> 84.499718 | J36: =I36*J$26 -> 93.794687 | ... W36: =V36*W$26 -> 499.59457
A37: 300 | B37: 49.2 | C37: =B37*C$26 -> 54.612 | D37: =C37*D$26 -> 60.61932 | E37: =D37*E$26 -> 67.287445 | F37: =E37*F$26 -> 74.689064 | G37: =F37*G$26 -> 82.904861 | H37: =G37*H$26 -> 92.024396 | I37: =H37*I$26 -> 102.14708 | J37: =I37*J$26 -> 113.38326 | ... W37: =V37*W$26 -> 603.9325
A38: 315 | B38: 44.7 | C38: =B38*C$26 -> 49.617 | D38: =C38*D$26 -> 55.07487 | E38: =D38*E$26 -> 61.133106 | F38: =E38*F$26 -> 67.857747 | G38: =F38*G$26 -> 75.3221 | H38: =G38*H$26 -> 83.60753 | I38: =H38*I$26 -> 92.804359 | J38: =I38*J$26 -> 103.01284 | ... W38: =V38*W$26 -> 548.69478
A39: 350 | B39: 53 | C39: =B39*C$26 -> 58.83 | D39: =C39*D$26 -> 65.3013 | E39: =D39*E$26 -> 72.484443 | F39: =E39*F$26 -> 80.457732 | G39: =F39*G$26 -> 89.308082 | H39: =G39*H$26 -> 99.131971 | I39: =H39*I$26 -> 110.03649 | J39: =I39*J$26 -> 122.1405 | ... W39: =V39*W$26 -> 650.5777
A40: 400 | B40: 56.8 | C40: =B40*C$26 -> 63.048 | D40: =C40*D$26 -> 69.98328 | E40: =D40*E$26 -> 77.681441 | F40: =E40*F$26 -> 86.226399 | G40: =F40*G$26 -> 95.711303 | H40: =G40*H$26 -> 106.23955 | I40: =H40*I$26 -> 117.9259 | J40: =I40*J$26 -> 130.89775 | ... W40: =V40*W$26 -> 697.22289
A41: 500 | B41: 73.2 | C41: =B41*C$26 -> 81.252 | D41: =C41*D$26 -> 90.18972 | E41: =D41*E$26 -> 100.11059 | F41: =E41*F$26 -> 111.12275 | G41: =F41*G$26 -> 123.34626 | H41: =G41*H$26 -> 136.91435 | I41: =H41*I$26 -> 151.97492 | J41: =I41*J$26 -> 168.69216 | ... W41: =V41*W$26 -> 898.53373
... A47: 1200 | B47: 272.9 | C47: =B47*C$26 -> 302.919 | D47: =C47*D$26 -> 336.24009 | E47: =D47*E$26 -> 373.2265 | F47: =E47*F$26 -> 414.28141 | G47: =F47*G$26 -> 459.85237 | H47: =G47*H$26 -> 510.43613 | I47: =H47*I$26 -> 566.58411 | J47: =I47*J$26 -> 628.90836 | ... W47: =V47*W$26 -> 3349.8614

Sheet Manhole Rate
B1: Up to 1.5 | C1: 1.5 - 2.0 | D1: 2.0 - 2.5 | E1: 2.5 - 3.0 | F1: 3.0 - 3.5 | G1: 3.5 - 4.0 | H1: 4.0 - 4.5 | I1: 4.5 - 5.0 | J1: 5.0 - 5.5 | K1: 5.5 - 6.0 | L1: 6.0 - 6.5 | M1: 6.5 - 7.0 | N1: 7.0 - 7.5 | O1: 7.5 - 8.0 | P1: 8.0 - 8.5 | Q1: 8.5 - 9.0 | R1: 9.0 - 9.5 | S1: 9.5 - 10.0 | T1: 10.0 - 10.5 | U1: 10.5 - 11.0 | V1: 11.0 - 11.5 | W1: 11.5 - 12.0 | X1: 12.0 - 12.5 | Y1: 12.5 - 13.0 | Z1: 13.0 - 13.5 | AA1: 13.5 - 14.0 | AB1: 14.0 - 14.5 | AC1: 14.5 - 15.0
A2: Type 1 - 1200 mm | B2: 703.81171 | C2: 813.60938 | D2: 884.92779 | E2: 1089.5107 | F2: 1253.9371 | G2: =F2*G$7 -> 1391.8702 | H2: =G2*H$7 -> 1544.9759 | I2: =H2*I$7 -> 1714.9232 | J2: =I2*J$7 -> 1903.5648 | K2: =J2*K$7 -> 2112.9569 | L2: =K2*L$7 -> 2746.844 | M2: =L2*M$7 -> 3048.9968 | N2: =M2*N$7 -> 3384.3865 | ... AC2: =AB2*AC$7 -> 22210.86
A3: Type 2 - 1500 mm | B3: 895.2 | C3: =B3*C7 -> 993.672 | D3: =C3*D7 -> 1102.9759 | E3: =D3*E7 -> 1224.3033 | F3: =E3*F7 -> 1358.9766 | G3: =F3*G7 -> 1508.4641 | H3: =G3*H7 -> 1674.3951 | I3: =H3*I7 -> 1858.5786 | J3: =I3*J7 -> 2063.0222 | ... AC3: =AB3*AC7 -> 24071.415
A4: Type 3 - 1800 mm | B4: =C4/C7 -> 1234.7521 | C4: 1370.5748 | D4: 1564.5066 | E4: 1764.0353 | F4: 1988.4946 | G4: 2207.7837 | H4: 2699.9699 | I4: 2992.553 | J4: 3291.6158 | K4: 3548.1071 | L4: 3864.5383 | M4: 4134.5475 | N4: 4391.3321 | O4: 4825.322 | P4: 5030.5 | Q4: 5235.6 | R4: 5440.7699 | S4: 7069.9 | T4: 8699.0725 | U4: =T4*U$7 -> 9655.9705 | V4: =U4*V$7 -> 10718.127 | W4: =V4*W$7 -> 11897.121 | X4: =W4*X$7 -> 15466.258 | Y4: =X4*Y$7 -> 17167.546 | Z4: =Y4*Z$7 -> 19055.976 | AA4: =Z4*AA$7 -> 21152.133 | AB4: =AA4*AB$7 -> 23478.868 | AC4: =AB4*AC$7 -> 26061.543
A6: Depth | B6: Up to 1.5 | C6: 1.5 - 2.0 | D6: 2.0 - 2.5 | E6: 2.5 - 3.0 | F6: 3.0 - 3.5 | G6: 3.5 - 4.0 | H6: 4.0 - 4.5 | I6: 4.5 - 5.0 | J6: 5.0 - 5.5 | K6: 5.5 - 6.0 | L6: 6.0 - 6.5 | M6: 6.5 - 7.0 | N6: 7.0 - 7.5 | O6: 7.5 - 8.0 | P6: 8.0 - 8.5 | Q6: 8.5 - 9.0 | R6: 9.0 - 9.5 | S6: 9.5 - 10.0 | T6: 10.0 - 10.5 | U6: 10.5 - 11.0 | V6: 11.0 - 11.5 | W6: 11.5 - 12.0 | X6: 12.0 - 12.5 | Y6: 12.5 - 13.0 | Z6: 13.0 - 13.5 | AA6: 13.5 - 14.0 | AB6: 14.0 - 14.5 | AC6: 14.5 - 15.0
A7: Growth | C7: 1.11 | D7: 1.11 | E7: 1.11 | F7: 1.11 | G7: 1.11 | H7: 1.11 | I7: 1.11 | J7: 1.11 | K7: 1.11 | L7: 1.3 | M7: 1.11 | N7: 1.11 | O7: 1.11 | P7: 1.11 | Q7: 1.11 | R7: 1.3 | S7: 1.11 | T7: 1.11 | U7: 1.11 | V7: 1.11 | W7: 1.11 | X7: 1.3 | Y7: 1.11 | Z7: 1.11 | AA7: 1.11 | AB7: 1.11 | AC7: 1.11

Sheet Sewer Pipes - CAPEX
A1: Sewer Pipe (mm) | B1: Depth (m) | C1: Rate (OMR/m) | D1: S1 | E1: S2 | F1: S3 | G1: S4 | H1: S5 | I1: S6 | J1: S7 | K1: S1 | L1: S2 | M1: S3 | N1: S4 | O1: S5 | P1: S6 | Q1: S7
D2: Length (m) | E2: Length (m) | F2: Length (m) | G2: Length (m) | H2: Length (m) | I2: Length (m) | J2: Length (m) | K2: Total Amount (OMR) | L2: Total Amount (OMR) | M2: Total Amount (OMR) | N2: Total Amount (OMR) | O2: Total Amount (OMR) | P2: Total Amount (OMR) | Q2: Total Amount (OMR)
A3: 200 | B3: Up to 1.5 | C3: =IFERROR(VLOOKUP($A3,'Pipe Rate'!$A$1:$AC$23,MATCH($B3,'Pipe Rate'!$B$1:$AC$1,0)+1,0),"N/F") -> 10.5 | D3: 41778 | E3: 41778 | F3: 41778 | G3: 41778 | H3: 41778 | I3: 41778 | J3: 41778 | K3: =IFERROR(D3*$C3,0) -> 438669 | L3: =IFERROR(E3*$C3,0) -> 438669 | M3: =IFERROR(F3*$C3,0) -> 438669 | N3: =IFERROR(G3*$C3,0) -> 438669 | O3: =IFERROR(H3*$C3,0) -> 438669 | P3: =IFERROR(I3*$C3,0) -> 438669 | Q3: =IFERROR(J3*$C3,0) -> 438669
A4: 200 | B4: 1.5 - 2.0 | C4: =IFERROR(VLOOKUP($A4,'Pipe Rate'!$A$1:$AC$23,MATCH($B4,'Pipe Rate'!$B$1:$AC$1,0)+1,0),"N/F") -> 11.655 | D4: 514857 | E4: 514747 | F4: 514857 | G4: 515009 | H4: 515043 | I4: 515043 | J4: 514857 | K4: =IFERROR(D4*$C4,0) -> 6000658.3 | L4: =IFERROR(E4*$C4,0) -> 5999376.3 | M4: =IFERROR(F4*$C4,0) -> 6000658.3 | N4: =IFERROR(G4*$C4,0) -> 6002429.9 | O4: =IFERROR(H4*$C4,0) -> 6002826.2 | P4: =IFERROR(I4*$C4,0) -> 6002826.2 | Q4: =IFERROR(J4*$C4,0) -> 6000658.3
A5: 200 | B5: 2.0 - 2.5 | C5: =IFERROR(VLOOKUP($A5,'Pipe Rate'!$A$1:$AC$23,MATCH($B5,'Pipe Rate'!$B$1:$AC$1,0)+1,0),"N/F") -> 12.93705 | D5: 205654 | E5: 205654 | F5: 205654 | G5: 205654 | H5: 205897 | I5: 206004 | J5: 205760 | K5: =IFERROR(D5*$C5,0) -> 2660556.1 | L5: =IFERROR(E5*$C5,0) -> 2660556.1 | M5: =IFERROR(F5*$C5,0) -> 2660556.1 | N5: =IFERROR(G5*$C5,0) -> 2660556.1 | O5: =IFERROR(H5*$C5,0) -> 2663699.8 | P5: =IFERROR(I5*$C5,0) -> 2665084 | Q5: =IFERROR(J5*$C5,0) -> 2661927.4
A6: 200 | B6: 2.5 - 3.0 | C6: =IFERROR(VLOOKUP($A6,'Pipe Rate'!$A$1:$AC$23,MATCH($B6,'Pipe Rate'!$B$1:$AC$1,0)+1,0),"N/F") -> 14.360126 | D6: 115195 | E6: 115195 | F6: 115299 | G6: 115399 | H6: 115541 | I6: 115601 | J6: 115255 | K6: =IFERROR(D6*$C6,0) -> 1654214.7 | L6: =IFERROR(E6*$C6,0) -> 1654214.7 | M6: =IFERROR(F6*$C6,0) -> 1655708.1 | N6: =IFERROR(G6*$C6,0) -> 1657144.1 | O6: =IFERROR(H6*$C6,0) -> 1659183.3 | P6: =IFERROR(I6*$C6,0) -> 1660044.9 | Q6: =IFERROR(J6*$C6,0) -> 1655076.3
A7: 200 | B7: 3.0 - 3.5 | C7: =IFERROR(VLOOKUP($A7,'Pipe Rate'!$A$1:$AC$23,MATCH($B7,'Pipe Rate'!$B$1:$AC$1,0)+1,0),"N/F") -> 15.939739 | D7: 91089 | E7: 91089 | F7: 91301 | G7: 91456 | H7: 91966 | I7: 92548 | J7: 91672 | K7: =IFERROR(D7*$C7,0) -> 1451934.9 | L7: =IFERROR(E7*$C7,0) -> 1451934.9 | M7: =IFERROR(F7*$C7,0) -> 1455314.1 | N7: =IFERROR(G7*$C7,0) -> 1457784.8 | O7: =IFERROR(H7*$C7,0) -> 1465914.1 | P7: =IFERROR(I7*$C7,0) -> 1475191 | Q7: =IFERROR(J7*$C7,0) -> 1461227.8
A8: 200 | B8: 3.5 - 4.0 | C8: =IFERROR(VLOOKUP($A8,'Pipe Rate'!$A$1:$AC$23,MATCH($B8,'Pipe Rate'!$B$1:$AC$1,0)+1,0),"N/F") -> 17.693111 | D8: 68027 | E8: 68027 | F8: 68532 | G8: 68615 | H8: 68961 | I8: 69555 | J8: 68620 | K8: =IFERROR(D8*$C8,0) -> 1203609.2 | L8: =IFERROR(E8*$C8,0) -> 1203609.2 | M8: =IFERROR(F8*$C8,0) -> 1212544.3 | N8: =IFERROR(G8*$C8,0) -> 1214012.8 | O8: =IFERROR(H8*$C8,0) -> 1220134.6 | P8: =IFERROR(I8*$C8,0) -> 1230644.3 | Q8: =IFERROR(J8*$C8,0) -> 1214101.3
A9: 200 | B9: 4.5 - 5.0 | C9: =IFERROR(VLOOKUP($A9,'Pipe Rate'!$A$1:$AC$23,MATCH($B9,'Pipe Rate'!$B$1:$AC$1,0)+1,0),"N/F") -> 21.799682 | D9: 89736 | E9: 89736 | F9: 90371 | G9: 90640 | H9: 91240 | I9: 92062 | J9: 90558 | K9: =IFERROR(D9*$C9,0) -> 1956216.2 | L9: =IFERROR(E9*$C9,0) -> 1956216.2 | M9: =IFERROR(F9*$C9,0) -> 1970059 | N9: =IFERROR(G9*$C9,0) -> 1975923.1 | O9: =IFERROR(H9*$C9,0) -> 1989002.9 | P9: =IFERROR(I9*$C9,0) -> 2006922.3 | Q9: =IFERROR(J9*$C9,0) -> 1974135.6
A10: 200 | B10: 5.5 - 6.0 | C10: =IFERROR(VLOOKUP($A10,'Pipe Rate'!$A$1:$AC$23,MATCH($B10,'Pipe Rate'!$B$1:$AC$1,0)+1,0),"N/F") -> 26.859388 | D10: 60258 | E10: 60258 | F10: 61204 | G10: 61543 | H10: 61880 | I10: 62380 | J10: 60758 | K10: =IFERROR(D10*$C10,0) -> 1618493 | L10: =IFERROR(E10*$C10,0) -> 1618493 | M10: =IFERROR(F10*$C10,0) -> 1643902 | N10: =IFERROR(G10*$C10,0) -> 1653007.3 | O10: =IFERROR(H10*$C10,0) -> 1662058.9 | P10: =IFERROR(I10*$C10,0) -> 1675488.6 | Q10: =IFERROR(J10*$C10,0) -> 1631922.7
A11: 200 | B11: 6.5 - 7.0 | C11: =IFERROR(VLOOKUP($A11,'Pipe Rate'!$A$1:$AC$23,MATCH($B11,'Pipe Rate'!$B$1:$AC$1,0)+1,0),"N/F") -> 38.758096 | D11: 35336 | E11: 35336 | F11: 35848 | G11: 36389 | H11: 36389 | I11: 36389 | J11: 35336 | K11: =IFERROR(D11*$C11,0) -> 1369556.1 | L11: =IFERROR(E11*$C11,0) -> 1369556.1 | M11: =IFERROR(F11*$C11,0) -> 1389400.2 | N11: =IFERROR(G11*$C11,0) -> 1410368.4 | O11: =IFERROR(H11*$C11,0) -> 1410368.4 | P11: =IFERROR(I11*$C11,0) -> 1410368.4 | Q11: =IFERROR(J11*$C11,0) -> 1369556.1
A12: 200 | B12: 7.5 - 8.0 | C12: =IFERROR(VLOOKUP($A12,'Pipe Rate'!$A$1:$AC$23,MATCH($B12,'Pipe Rate'!$B$1:$AC$1,0)+1,0),"N/F") -> 47.753851 | D12: 27781 | E12: 27410 | F12: 27781 | G12: 29074 | H12: 29074 | I12: 29074 | J12: 27781 | K12: =IFERROR(D12*$C12,0) -> 1326649.7 | L12: =IFERROR(E12*$C12,0) -> 1308933 | M12: =IFERROR(F12*$C12,0) -> 1326649.7 | N12: =IFERROR(G12*$C12,0) -> 1388395.5 | O12: =IFERROR(H12*$C12,0) -> 1388395.5 | P12: =IFERROR(I12*$C12,0) -> 1388395.5 | Q12: =IFERROR(J12*$C12,0) -> 1326649.7
A13: 200 | B13: 8.5 - 9.0 | C13: =IFERROR(VLOOKUP($A13,'Pipe Rate'!$A$1:$AC$23,MATCH($B13,'Pipe Rate'!$B$1:$AC$1,0)+1,0),"N/F") -> 58.837519 | D13: 15235 | E13: 14893 | F13: 15235 | G13: 15837 | H13: 15837 | I13: 15837 | J13: 15235 | K13: =IFERROR(D13*$C13,0) -> 896389.61 | L13: =IFERROR(E13*$C13,0) -> 876267.18 | M13: =IFERROR(F13*$C13,0) -> 896389.61 | N13: =IFERROR(G13*$C13,0) -> 931809.79 | O13: =IFERROR(H13*$C13,0) -> 931809.79 | P13: =IFERROR(I13*$C13,0) -> 931809.79 | Q13: =IFERROR(J13*$C13,0) -> 896389.61
A14: 200 | B14: 9.5 - 10.0 | C14: =IFERROR(VLOOKUP($A14,'Pipe Rate'!$A$1:$AC$23,MATCH($B14,'Pipe Rate'!$B$1:$AC$1,0)+1,0),"N/F") -> 84.90254 | D14: 8218 | E14: 7812 | F14: 8218 | G14: 8218 | H14: 8218 | I14: 8218 | J14: 8218 | K14: =IFERROR(D14*$C14,0) -> 697729.08 | L14: =IFERROR(E14*$C14,0) -> 663258.65 | M14: =IFERROR(F14*$C14,0) -> 697729.08 | N14: =IFERROR(G14*$C14,0) -> 697729.08 | O14: =IFERROR(H14*$C14,0) -> 697729.08 | P14: =IFERROR(I14*$C14,0) -> 697729.08 | Q14: =IFERROR(J14*$C14,0) -> 697729.08
... A71: 355 | B71: 10.5 - 11.0 | C71: =IFERROR(VLOOKUP($A71,'Pipe Rate'!$A$1:$AC$23,MATCH($B71,'Pipe Rate'!$B$1:$AC$1,0)+1,0),"N/F") -> 256.04156 | D71: 726 | E71: 726 | F71: 726 | G71: 726 | H71: 726 | I71: 726 | J71: 726 | K71: =IFERROR(D71*$C71,0) -> 185886.17 | L71: =IFERROR(E71*$C71,0) -> 185886.17 | M71: =IFERROR(F71*$C71,0) -> 185886.17 | N71: =IFERROR(G71*$C71,0) -> 185886.17 | O71: =IFERROR(H71*$C71,0) -> 185886.17 | P71: =IFERROR(I71*$C71,0) -> 185886.17 | Q71: =IFERROR(J71*$C71,0) -> 185886.17
A72: 450 | B72: 1.5 - 2.0 | C72: =IFERROR(VLOOKUP($A72,'Pipe Rate'!$A$1:$AC$23,MATCH($B72,'Pipe Rate'!$B$1:$AC$1,0)+1,0),"N/F") -> 37.74 | D72: 659 | F72: 659 | G72: 659 | H72: 659 | I72: 659 | J72: 659 | K72: =IFERROR(D72*$C72,0) -> 24870.66 | L72: =IFERROR(E72*$C72,0) -> 0 | M72: =IFERROR(F72*$C72,0) -> 24870.66 | N72: =IFERROR(G72*$C72,0) -> 24870.66 | O72: =IFERROR(H72*$C72,0) -> 24870.66 | P72: =IFERROR(I72*$C72,0) -> 24870.66 | Q72: =IFERROR(J72*$C72,0) -> 24870.66
A73: 450 | B73: 2.0 - 2.5 | C73: =IFERROR(VLOOKUP($A73,'Pipe Rate'!$A$1:$AC$23,MATCH($B73,'Pipe Rate'!$B$1:$AC$1,0)+1,0),"N/F") -> 41.8914 | D73: 168 | F73: 168 | G73: 168 | H73: 168 | I73: 168 | J73: 168 | K73: =IFERROR(D73*$C73,0) -> 7037.7552 | L73: =IFERROR(E73*$C73,0) -> 0 | M73: =IFERROR(F73*$C73,0) -> 7037.7552 | N73: =IFERROR(G73*$C73,0) -> 7037.7552 | O73: =IFERROR(H73*$C73,0) -> 7037.7552 | P73: =IFERROR(I73*$C73,0) -> 7037.7552 | Q73: =IFERROR(J73*$C73,0) -> 7037.7552
A74: 450 | B74: 2.5 - 3.0 | C74: =IFERROR(VLOOKUP($A74,'Pipe Rate'!$A$1:$AC$23,MATCH($B74,'Pipe Rate'!$B$1:$AC$1,0)+1,0),"N/F") -> 46.499454 | D74: 344 | E74: 200 | F74: 344 | G74: 344 | H74: 344 | I74: 344 | J74: 344 | K74: =IFERROR(D74*$C74,0) -> 15995.812 | L74: =IFERROR(E74*$C74,0) -> 9299.8908 | M74: =IFERROR(F74*$C74,0) -> 15995.812 | N74: =IFERROR(G74*$C74,0) -> 15995.812 | O74: =IFERROR(H74*$C74,0) -> 15995.812 | P74: =IFERROR(I74*$C74,0) -> 15995.812 | Q74: =IFERROR(J74*$C74,0) -> 15995.812
A75: 450 | B75: 3.0 - 3.5 | C75: =IFERROR(VLOOKUP($A75,'Pipe Rate'!$A$1:$AC$23,MATCH($B75,'Pipe Rate'!$B$1:$AC$1,0)+1,0),"N/F") -> 51.614394 | D75: 567 | E75: 467 | F75: 567 | G75: 567 | H75: 567 | I75: 567 | J75: 567 | K75: =IFERROR(D75*$C75,0) -> 29265.361 | L75: =IFERROR(E75*$C75,0) -> 24103.922 | M75: =IFERROR(F75*$C75,0) -> 29265.361 | N75: =IFERROR(G75*$C75,0) -> 29265.361 | O75: =IFERROR(H75*$C75,0) -> 29265.361 | P75: =IFERROR(I75*$C75,0) -> 29265.361 | Q75: =IFERROR(J75*$C75,0) -> 29265.361
A76: 450 | B76: 3.5 - 4.0 | C76: =IFERROR(VLOOKUP($A76,'Pipe Rate'!$A$1:$AC$23,MATCH($B76,'Pipe Rate'!$B$1:$AC$1,0)+1,0),"N/F") -> 57.291977 | D76: 339 | E76: 339 | F76: 339 | G76: 339 | H76: 339 | I76: 339 | J76: 339 | K76: =IFERROR(D76*$C76,0) -> 19421.98 | L76: =IFERROR(E76*$C76,0) -> 19421.98 | M76: =IFERROR(F76*$C76,0) -> 19421.98 | N76: =IFERROR(G76*$C76,0) -> 19421.98 | O76: =IFERROR(H76*$C76,0) -> 19421.98 | P76: =IFERROR(I76*$C76,0) -> 19421.98 | Q76: =IFERROR(J76*$C76,0) -> 19421.98
A77: 450 | B77: 4.5 - 5.0 | C77: =IFERROR(VLOOKUP($A77,'Pipe Rate'!$A$1:$AC$23,MATCH($B77,'Pipe Rate'!$B$1:$AC$1,0)+1,0),"N/F") -> 70.589445 | D77: 927 | E77: 927 | F77: 927 | G77: 927 | H77: 927 | I77: 927 | J77: 927 | K77: =IFERROR(D77*$C77,0) -> 65436.416 | L77: =IFERROR(E77*$C77,0) -> 65436.416 | M77: =IFERROR(F77*$C77,0) -> 65436.416 | N77: =IFERROR(G77*$C77,0) -> 65436.416 | O77: =IFERROR(H77*$C77,0) -> 65436.416 | P77: =IFERROR(I77*$C77,0) -> 65436.416 | Q77: =IFERROR(J77*$C77,0) -> 65436.416
A78: 450 | B78: 5.5 - 6.0 | C78: =IFERROR(VLOOKUP($A78,'Pipe Rate'!$A$1:$AC$23,MATCH($B78,'Pipe Rate'!$B$1:$AC$1,0)+1,0),"N/F") -> 86.973255 | D78: 2260 | E78: 2052 | F78: 2260 | G78: 2260 | H78: 2260 | I78: 2260 | J78: 2260 | K78: =IFERROR(D78*$C78,0) -> 196559.56 | L78: =IFERROR(E78*$C78,0) -> 178469.12 | M78: =IFERROR(F78*$C78,0) -> 196559.56 | N78: =IFERROR(G78*$C78,0) -> 196559.56 | O78: =IFERROR(H78*$C78,0) -> 196559.56 | P78: =IFERROR(I78*$C78,0) -> 196559.56 | Q78: =IFERROR(J78*$C78,0) -> 196559.56
A79: 450 | B79: 6.5 - 7.0 | C79: =IFERROR(VLOOKUP($A79,'Pipe Rate'!$A$1:$AC$23,MATCH($B79,'Pipe Rate'!$B$1:$AC$1,0)+1,0),"N/F") -> 125.50241 | D79: 1006 | E79: 886 | F79: 1006 | G79: 1006 | H79: 1006 | I79: 1006 | J79: 1006 | K79: =IFERROR(D79*$C79,0) -> 126255.42 | L79: =IFERROR(E79*$C79,0) -> 111195.13 | M79: =IFERROR(F79*$C79,0) -> 126255.42 | N79: =IFERROR(G79*$C79,0) -> 126255.42 | O79: =IFERROR(H79*$C79,0) -> 126255.42 | P79: =IFERROR(I79*$C79,0) -> 126255.42 | Q79: =IFERROR(J79*$C79,0) -> 126255.42
A80: 450 | B80: 7.5 - 8.0 | C80: =IFERROR(VLOOKUP($A80,'Pipe Rate'!$A$1:$AC$23,MATCH($B80,'Pipe Rate'!$B$1:$AC$1,0)+1,0),"N/F") -> 154.63152 | D80: 2283 | E80: 2121 | F80: 2283 | G80: 2283 | H80: 2283 | I80: 2283 | J80: 2283 | K80: =IFERROR(D80*$C80,0) -> 353023.75 | L80: =IFERROR(E80*$C80,0) -> 327973.45 | M80: =IFERROR(F80*$C80,0) -> 353023.75 | N80: =IFERROR(G80*$C80,0) -> 353023.75 | O80: =IFERROR(H80*$C80,0) -> 353023.75 | P80: =IFERROR(I80*$C80,0) -> 353023.75 | Q80: =IFERROR(J80*$C80,0) -> 353023.75
A81: 450 | B81: 8.5 - 9.0 | C81: =IFERROR(VLOOKUP($A81,'Pipe Rate'!$A$1:$AC$23,MATCH($B81,'Pipe Rate'!$B$1:$AC$1,0)+1,0),"N/F") -> 190.52149 | D81: 625 | E81: 625 | F81: 625 | G81: 625 | H81: 625 | I81: 625 | J81: 625 | K81: =IFERROR(D81*$C81,0) -> 119075.93 | L81: =IFERROR(E81*$C81,0) -> 119075.93 | M81: =IFERROR(F81*$C81,0) -> 119075.93 | N81: =IFERROR(G81*$C81,0) -> 119075.93 | O81: =IFERROR(H81*$C81,0) -> 119075.93 | P81: =IFERROR(I81*$C81,0) -> 119075.93 | Q81: =IFERROR(J81*$C81,0) -> 119075.93
A82: 450 | B82: 9.5 - 10.0 | C82: =IFERROR(VLOOKUP($A82,'Pipe Rate'!$A$1:$AC$23,MATCH($B82,'Pipe Rate'!$B$1:$AC$1,0)+1,0),"N/F") -> 274.92251 | D82: 800 | E82: 800 | F82: 800 | G82: 800 | H82: 800 | I82: 800 | J82: 800 | K82: =IFERROR(D82*$C82,0) -> 219938.01 | L82: =IFERROR(E82*$C82,0) -> 219938.01 | M82: =IFERROR(F82*$C82,0) -> 219938.01 | N82: =IFERROR(G82*$C82,0) -> 219938.01 | O82: =IFERROR(H82*$C82,0) -> 219938.01 | P82: =IFERROR(I82*$C82,0) -> 219938.01 | Q82: =IFERROR(J82*$C82,0) -> 219938.01
A83: 450 | B83: 10.5 - 11.0 | C83: =IFERROR(VLOOKUP($A83,'Pipe Rate'!$A$1:$AC$23,MATCH($B83,'Pipe Rate'!$B$1:$AC$1,0)+1,0),"N/F") -> 338.73203 | D83: 383 | E83: 383 | F83: 383 | G83: 383 | H83: 383 | I83: 383 | J83: 383 | K83: =IFERROR(D83*$C83,0) -> 129734.37 | L83: =IFERROR(E83*$C83,0) -> 129734.37 | M83: =IFERROR(F83*$C83,0) -> 129734.37 | N83: =IFERROR(G83*$C83,0) -> 129734.37 | O83: =IFERROR(H83*$C83,0) -> 129734.37 | P83: =IFERROR(I83*$C83,0) -> 129734.37 | Q83: =IFERROR(J83*$C83,0) -> 129734.37
A84: 500 | B84: 1.5 - 2.0 | C84: =IFERROR(VLOOKUP($A84,'Pipe Rate'!$A$1:$AC$23,MATCH($B84,'Pipe Rate'!$B$1:$AC$1,0)+1,0),"N/F") -> 38.85 | D84: 176 | E84: 176 | F84: 176 | G84: 176 | H84: 176 | I84: 176 | J84: 176 | K84: =IFERROR(D84*$C84,0) -> 6837.6 | L84: =IFERROR(E84*$C84,0) -> 6837.6 | M84: =IFERROR(F84*$C84,0) -> 6837.6 | N84: =IFERROR(G84*$C84,0) -> 6837.6 | O84: =IFERROR(H84*$C84,0) -> 6837.6 | P84: =IFERROR(I84*$C84,0) -> 6837.6 | Q84: =IFERROR(J84*$C84,0) -> 6837.6
A85: 500 | B85: 2.0 - 2.5 | C85: =IFERROR(VLOOKUP($A85,'Pipe Rate'!$A$1:$AC$23,MATCH($B85,'Pipe Rate'!$B$1:$AC$1,0)+1,0),"N/F") -> 43.1235 | D85: 865 | E85: 865 | F85: 865 | G85: 865 | H85: 865 | I85: 865 | J85: 865 | K85: =IFERROR(D85*$C85,0) -> 37301.828 | L85: =IFERROR(E85*$C85,0) -> 37301.828 | M85: =IFERROR(F85*$C85,0) -> 37301.828 | N85: =IFERROR(G85*$C85,0) -> 37301.828 | O85: =IFERROR(H85*$C85,0) -> 37301.828 | P85: =IFERROR(I85*$C85,0) -> 37301.828 | Q85: =IFERROR(J85*$C85,0) -> 37301.828
... A127: 710 | B127: 8.5 - 9.0 | C127: =IFERROR(VLOOKUP($A127,'Pipe Rate'!$A$1:$AC$23,MATCH($B127,'Pipe Rate'!$B$1:$AC$1,0)+1,0),"N/F") -> 332.2919 | D127: 554 | E127: 554 | F127: 554 | G127: 936 | H127: 936 | I127: 1295 | J127: 914 | K127: =IFERROR(D127*$C127,0) -> 184089.71 | L127: =IFERROR(E127*$C127,0) -> 184089.71 | M127: =IFERROR(F127*$C127,0) -> 184089.71 | N127: =IFERROR(G127*$C127,0) -> 311025.21 | O127: =IFERROR(H127*$C127,0) -> 311025.21 | P127: =IFERROR(I127*$C127,0) -> 430318 | Q127: =IFERROR(J127*$C127,0) -> 303714.79
A128: 710 | B128: 9.5 - 10.0 | C128: =IFERROR(VLOOKUP($A128,'Pipe Rate'!$A$1:$AC$23,MATCH($B128,'Pipe Rate'!$B$1:$AC$1,0)+1,0),"N/F") -> 479.4972 | I128: 197 | J128: 197 | K128: =IFERROR(D128*$C128,0) -> 0 | L128: =IFERROR(E128*$C128,0) -> 0 | M128: =IFERROR(F128*$C128,0) -> 0 | N128: =IFERROR(G128*$C128,0) -> 0 | O128: =IFERROR(H128*$C128,0) -> 0 | P128: =IFERROR(I128*$C128,0) -> 94460.949 | Q128: =IFERROR(J128*$C128,0) -> 94460.949
A129: 710 | B129: 10.5 - 11.0 | C129: =IFERROR(VLOOKUP($A129,'Pipe Rate'!$A$1:$AC$23,MATCH($B129,'Pipe Rate'!$B$1:$AC$1,0)+1,0),"N/F") -> 590.78851 | D129: 288 | E129: 288 | F129: 288 | G129: 288 | H129: 288 | I129: 389 | J129: 389 | K129: =IFERROR(D129*$C129,0) -> 170147.09 | L129: =IFERROR(E129*$C129,0) -> 170147.09 | M129: =IFERROR(F129*$C129,0) -> 170147.09 | N129: =IFERROR(G129*$C129,0) -> 170147.09 | O129: =IFERROR(H129*$C129,0) -> 170147.09 | P129: =IFERROR(I129*$C129,0) -> 229816.73 | Q129: =IFERROR(J129*$C129,0) -> 229816.73
A130: 710 | B130: 11.5 - 12.0 | C130: =IFERROR(VLOOKUP($A130,'Pipe Rate'!$A$1:$AC$23,MATCH($B130,'Pipe Rate'!$B$1:$AC$1,0)+1,0),"N/F") -> 727.91052 | D130: 960 | E130: 960 | F130: 960 | G130: 960 | H130: 960 | I130: 1348 | J130: 1348 | K130: =IFERROR(D130*$C130,0) -> 698794.1 | L130: =IFERROR(E130*$C130,0) -> 698794.1 | M130: =IFERROR(F130*$C130,0) -> 698794.1 | N130: =IFERROR(G130*$C130,0) -> 698794.1 | O130: =IFERROR(H130*$C130,0) -> 698794.1 | P130: =IFERROR(I130*$C130,0) -> 981223.38 | Q130: =IFERROR(J130*$C130,0) -> 981223.38
A131: 710 | B131: 12.5 - 13.0 | C131: =IFERROR(VLOOKUP($A131,'Pipe Rate'!$A$1:$AC$23,MATCH($B131,'Pipe Rate'!$B$1:$AC$1,0)+1,0),"N/F") -> 1050.3749 | I131: 222 | J131: 222 | K131: =IFERROR(D131*$C131,0) -> 0 | L131: =IFERROR(E131*$C131,0) -> 0 | M131: =IFERROR(F131*$C131,0) -> 0 | N131: =IFERROR(G131*$C131,0) -> 0 | O131: =IFERROR(H131*$C131,0) -> 0 | P131: =IFERROR(I131*$C131,0) -> 233183.22 | Q131: =IFERROR(J131*$C131,0) -> 233183.22
A132: 710 | B132: 13.5 - 14.0 | C132: =IFERROR(VLOOKUP($A132,'Pipe Rate'!$A$1:$AC$23,MATCH($B132,'Pipe Rate'!$B$1:$AC$1,0)+1,0),"N/F") -> 1294.1669 | I132: 100 | J132: 100 | K132: =IFERROR(D132*$C132,0) -> 0 | L132: =IFERROR(E132*$C132,0) -> 0 | M132: =IFERROR(F132*$C132,0) -> 0 | N132: =IFERROR(G132*$C132,0) -> 0 | O132: =IFERROR(H132*$C132,0) -> 0 | P132: =IFERROR(I132*$C132,0) -> 129416.69 | Q132: =IFERROR(J132*$C132,0) -> 129416.69
A133: 710 | B133: 14.5 - 15.0 | C133: =IFERROR(VLOOKUP($A133,'Pipe Rate'!$A$1:$AC$23,MATCH($B133,'Pipe Rate'!$B$1:$AC$1,0)+1,0),"N/F") -> 1594.543 | I133: 252 | J133: 252 | K133: =IFERROR(D133*$C133,0) -> 0 | L133: =IFERROR(E133*$C133,0) -> 0 | M133: =IFERROR(F133*$C133,0) -> 0 | N133: =IFERROR(G133*$C133,0) -> 0 | O133: =IFERROR(H133*$C133,0) -> 0 | P133: =IFERROR(I133*$C133,0) -> 401824.84 | Q133: =IFERROR(J133*$C133,0) -> 401824.84
A134: 800 | B134: 2.0 - 2.5 | C134: =IFERROR(VLOOKUP($A134,'Pipe Rate'!$A$1:$AC$23,MATCH($B134,'Pipe Rate'!$B$1:$AC$1,0)+1,0),"N/F") -> 105.46776 | D134: 434 | E134: 434 | F134: 434 | G134: 434 | H134: 434 | I134: 434 | J134: 434 | K134: =IFERROR(D134*$C134,0) -> 45773.008 | L134: =IFERROR(E134*$C134,0) -> 45773.008 | M134: =IFERROR(F134*$C134,0) -> 45773.008 | N134: =IFERROR(G134*$C134,0) -> 45773.008 | O134: =IFERROR(H134*$C134,0) -> 45773.008 | P134: =IFERROR(I134*$C134,0) -> 45773.008 | Q134: =IFERROR(J134*$C134,0) -> 45773.008
A135: 800 | B135: 2.5 - 3.0 | C135: =IFERROR(VLOOKUP($A135,'Pipe Rate'!$A$1:$AC$23,MATCH($B135,'Pipe Rate'!$B$1:$AC$1,0)+1,0),"N/F") -> 117.06921 | D135: 414 | E135: 414 | F135: 414 | G135: 414 | H135: 414 | I135: 414 | J135: 414 | K135: =IFERROR(D135*$C135,0) -> 48466.654 | L135: =IFERROR(E135*$C135,0) -> 48466.654 | M135: =IFERROR(F135*$C135,0) -> 48466.654 | N135: =IFERROR(G135*$C135,0) -> 48466.654 | O135: =IFERROR(H135*$C135,0) -> 48466.654 | P135: =IFERROR(I135*$C135,0) -> 48466.654 | Q135: =IFERROR(J135*$C135,0) -> 48466.654
A136: 800 | B136: 3.0 - 3.5 | C136: =IFERROR(VLOOKUP($A136,'Pipe Rate'!$A$1:$AC$23,MATCH($B136,'Pipe Rate'!$B$1:$AC$1,0)+1,0),"N/F") -> 129.94683 | D136: 277 | E136: 277 | F136: 277 | G136: 334 | H136: 334 | I136: 334 | J136: 277 | K136: =IFERROR(D136*$C136,0) -> 35995.271 | L136: =IFERROR(E136*$C136,0) -> 35995.271 | M136: =IFERROR(F136*$C136,0) -> 35995.271 | N136: =IFERROR(G136*$C136,0) -> 43402.24 | O136: =IFERROR(H136*$C136,0) -> 43402.24 | P136: =IFERROR(I136*$C136,0) -> 43402.24 | Q136: =IFERROR(J136*$C136,0) -> 35995.271
A137: 800 | B137: 3.5 - 4.0 | C137: =IFERROR(VLOOKUP($A137,'Pipe Rate'!$A$1:$AC$23,MATCH($B137,'Pipe Rate'!$B$1:$AC$1,0)+1,0),"N/F") -> 144.24098 | D137: 412 | E137: 412 | F137: 412 | G137: 553 | H137: 553 | I137: 553 | J137: 412 | K137: =IFERROR(D137*$C137,0) -> 59427.283 | L137: =IFERROR(E137*$C137,0) -> 59427.283 | M137: =IFERROR(F137*$C137,0) -> 59427.283 | N137: =IFERROR(G137*$C137,0) -> 79765.261 | O137: =IFERROR(H137*$C137,0) -> 79765.261 | P137: =IFERROR(I137*$C137,0) -> 79765.261 | Q137: =IFERROR(J137*$C137,0) -> 59427.283
...

Sheet Manholes - CAPEX
A1: Manholes | B1: Depth (m) | C1: Rate (OMR/m) | D1: S1 | E1: S2 | F1: S3 | G1: S4 | H1: S5 | I1: S6 | J1: S7 | K1: S1 | L1: S2 | M1: S3 | N1: S4 | O1: S5 | P1: S6 | Q1: S7
D2: Quantity (No.) | E2: Quantity (No.) | F2: Quantity (No.) | G2: Quantity (No.) | H2: Quantity (No.) | I2: Quantity (No.) | J2: Quantity (No.) | K2: Total Amount (OMR) | L2: Total Amount (OMR) | M2: Total Amount (OMR) | N2: Total Amount (OMR) | O2: Total Amount (OMR) | P2: Total Amount (OMR) | Q2: Total Amount (OMR)
A3: Type 1 - 1200 mm | B3: Up to 1.5 | C3: =IFERROR(VLOOKUP($A3,'Manhole Rate'!$A$1:$AC$4,MATCH($B3,'Manhole Rate'!$B$1:$AC$1,0)+1,0),"N/F") -> 703.81171 | D3: 3315 | E3: 3314 | F3: 3315 | G3: 3316 | H3: 3317 | I3: 3318 | J3: 3316 | K3: =IFERROR(D3*$C3,0) -> 2333135.8 | L3: =IFERROR(E3*$C3,0) -> 2332432 | M3: =IFERROR(F3*$C3,0) -> 2333135.8 | N3: =IFERROR(G3*$C3,0) -> 2333839.6 | O3: =IFERROR(H3*$C3,0) -> 2334543.4 | P3: =IFERROR(I3*$C3,0) -> 2335247.2 | Q3: =IFERROR(J3*$C3,0) -> 2333839.6
A4: Type 1 - 1200 mm | B4: 1.5 - 2.0 | C4: =IFERROR(VLOOKUP($A4,'Manhole Rate'!$A$1:$AC$4,MATCH($B4,'Manhole Rate'!$B$1:$AC$1,0)+1,0),"N/F") -> 813.60938 | D4: 4210 | E4: 4202 | F4: 4210 | G4: 4211 | H4: 4211 | I4: 4206 | J4: 4205 | K4: =IFERROR(D4*$C4,0) -> 3425295.5 | L4: =IFERROR(E4*$C4,0) -> 3418786.6 | M4: =IFERROR(F4*$C4,0) -> 3425295.5 | N4: =IFERROR(G4*$C4,0) -> 3426109.1 | O4: =IFERROR(H4*$C4,0) -> 3426109.1 | P4: =IFERROR(I4*$C4,0) -> 3422041.1 | Q4: =IFERROR(J4*$C4,0) -> 3421227.5
A5: Type 1 - 1200 mm | B5: 2.0 - 2.5 | C5: =IFERROR(VLOOKUP($A5,'Manhole Rate'!$A$1:$AC$4,MATCH($B5,'Manhole Rate'!$B$1:$AC$1,0)+1,0),"N/F") -> 884.92779 | D5: 2667 | E5: 2663 | F5: 2669 | G5: 2671 | H5: 2688 | I5: 2684 | J5: 2663 | K5: =IFERROR(D5*$C5,0) -> 2360102.4 | L5: =IFERROR(E5*$C5,0) -> 2356562.7 | M5: =IFERROR(F5*$C5,0) -> 2361872.3 | N5: =IFERROR(G5*$C5,0) -> 2363642.1 | O5: =IFERROR(H5*$C5,0) -> 2378685.9 | P5: =IFERROR(I5*$C5,0) -> 2375146.2 | Q5: =IFERROR(J5*$C5,0) -> 2356562.7
A6: Type 1 - 1200 mm | B6: 2.5 - 3.0 | C6: =IFERROR(VLOOKUP($A6,'Manhole Rate'!$A$1:$AC$4,MATCH($B6,'Manhole Rate'!$B$1:$AC$1,0)+1,0),"N/F") -> 1089.5107 | D6: 1594 | E6: 1594 | F6: 1599 | G6: 1600 | H6: 1607 | I6: 1605 | J6: 1592 | K6: =IFERROR(D6*$C6,0) -> 1736680 | L6: =IFERROR(E6*$C6,0) -> 1736680 | M6: =IFERROR(F6*$C6,0) -> 1742127.6 | N6: =IFERROR(G6*$C6,0) -> 1743217.1 | O6: =IFERROR(H6*$C6,0) -> 1750843.7 | P6: =IFERROR(I6*$C6,0) -> 1748664.7 | Q6: =IFERROR(J6*$C6,0) -> 1734501
A7: Type 1 - 1200 mm | B7: 3.0 - 3.5 | C7: =IFERROR(VLOOKUP($A7,'Manhole Rate'!$A$1:$AC$4,MATCH($B7,'Manhole Rate'!$B$1:$AC$1,0)+1,0),"N/F") -> 1253.9371 | D7: 1236 | E7: 1235 | F7: 1242 | G7: 1243 | H7: 1250 | I7: 1249 | J7: 1235 | K7: =IFERROR(D7*$C7,0) -> 1549866.2 | L7: =IFERROR(E7*$C7,0) -> 1548612.3 | M7: =IFERROR(F7*$C7,0) -> 1557389.9 | N7: =IFERROR(G7*$C7,0) -> 1558643.8 | O7: =IFERROR(H7*$C7,0) -> 1567421.4 | P7: =IFERROR(I7*$C7,0) -> 1566167.4 | Q7: =IFERROR(J7*$C7,0) -> 1548612.3
A8: Type 1 - 1200 mm | B8: 3.5 - 4.0 | C8: =IFERROR(VLOOKUP($A8,'Manhole Rate'!$A$1:$AC$4,MATCH($B8,'Manhole Rate'!$B$1:$AC$1,0)+1,0),"N/F") -> 1391.8702 | D8: 968 | E8: 967 | F8: 975 | G8: 978 | H8: 986 | I8: 986 | J8: 968 | K8: =IFERROR(D8*$C8,0) -> 1347330.3 | L8: =IFERROR(E8*$C8,0) -> 1345938.5 | M8: =IFERROR(F8*$C8,0) -> 1357073.4 | N8: =IFERROR(G8*$C8,0) -> 1361249 | O8: =IFERROR(H8*$C8,0) -> 1372384 | P8: =IFERROR(I8*$C8,0) -> 1372384 | Q8: =IFERROR(J8*$C8,0) -> 1347330.3
A9: Type 1 - 1200 mm | B9: 4.5 - 5.0 | C9: =IFERROR(VLOOKUP($A9,'Manhole Rate'!$A$1:$AC$4,MATCH($B9,'Manhole Rate'!$B$1:$AC$1,0)+1,0),"N/F") -> 1714.9232 | D9: 1403 | E9: 1403 | F9: 1428 | G9: 1448 | H9: 1454 | I9: 1460 | J9: 1409 | K9: =IFERROR(D9*$C9,0) -> 2406037.3 | L9: =IFERROR(E9*$C9,0) -> 2406037.3 | M9: =IFERROR(F9*$C9,0) -> 2448910.4 | N9: =IFERROR(G9*$C9,0) -> 2483208.8 | O9: =IFERROR(H9*$C9,0) -> 2493498.4 | P9: =IFERROR(I9*$C9,0) -> 2503787.9 | Q9: =IFERROR(J9*$C9,0) -> 2416326.8
A10: Type 1 - 1200 mm | B10: 5.5 - 6.0 | C10: =IFERROR(VLOOKUP($A10,'Manhole Rate'!$A$1:$AC$4,MATCH($B10,'Manhole Rate'!$B$1:$AC$1,0)+1,0),"N/F") -> 2112.9569 | D10: 962 | E10: 962 | F10: 982 | G10: 995 | H10: 1003 | I10: 1008 | J10: 967 | K10: =IFERROR(D10*$C10,0) -> 2032664.6 | L10: =IFERROR(E10*$C10,0) -> 2032664.6 | M10: =IFERROR(F10*$C10,0) -> 2074923.7 | N10: =IFERROR(G10*$C10,0) -> 2102392.1 | O10: =IFERROR(H10*$C10,0) -> 2119295.8 | P10: =IFERROR(I10*$C10,0) -> 2129860.6 | Q10: =IFERROR(J10*$C10,0) -> 2043229.3
A11: Type 1 - 1200 mm | B11: 6.5 - 7.0 | C11: =IFERROR(VLOOKUP($A11,'Manhole Rate'!$A$1:$AC$4,MATCH($B11,'Manhole Rate'!$B$1:$AC$1,0)+1,0),"N/F") -> 3048.9968 | D11: 678 | E11: 676 | F11: 694 | G11: 715 | H11: 732 | I11: 730 | J11: 676 | K11: =IFERROR(D11*$C11,0) -> 2067219.9 | L11: =IFERROR(E11*$C11,0) -> 2061121.9 | M11: =IFERROR(F11*$C11,0) -> 2116003.8 | N11: =IFERROR(G11*$C11,0) -> 2180032.7 | O11: =IFERROR(H11*$C11,0) -> 2231865.7 | P11: =IFERROR(I11*$C11,0) -> 2225767.7 | Q11: =IFERROR(J11*$C11,0) -> 2061121.9
A12: Type 1 - 1200 mm | B12: 7.5 - 8.0 | C12: =IFERROR(VLOOKUP($A12,'Manhole Rate'!$A$1:$AC$4,MATCH($B12,'Manhole Rate'!$B$1:$AC$1,0)+1,0),"N/F") -> 3756.669 | D12: 617 | E12: 612 | F12: 626 | G12: 652 | H12: 659 | I12: 662 | J12: 620 | K12: =IFERROR(D12*$C12,0) -> 2317864.8 | L12: =IFERROR(E12*$C12,0) -> 2299081.4 | M12: =IFERROR(F12*$C12,0) -> 2351674.8 | N12: =IFERROR(G12*$C12,0) -> 2449348.2 | O12: =IFERROR(H12*$C12,0) -> 2475644.9 | P12: =IFERROR(I12*$C12,0) -> 2486914.9 | Q12: =IFERROR(J12*$C12,0) -> 2329134.8
A13: Type 1 - 1200 mm | B13: 8.5 - 9.0 | C13: =IFERROR(VLOOKUP($A13,'Manhole Rate'!$A$1:$AC$4,MATCH($B13,'Manhole Rate'!$B$1:$AC$1,0)+1,0),"N/F") -> 4628.5919 | D13: 436 | E13: 429 | F13: 441 | G13: 454 | H13: 458 | I13: 458 | J13: 436 | K13: =IFERROR(D13*$C13,0) -> 2018066.1 | L13: =IFERROR(E13*$C13,0) -> 1985665.9 | M13: =IFERROR(F13*$C13,0) -> 2041209 | N13: =IFERROR(G13*$C13,0) -> 2101380.7 | O13: =IFERROR(H13*$C13,0) -> 2119895.1 | P13: =IFERROR(I13*$C13,0) -> 2119895.1 | Q13: =IFERROR(J13*$C13,0) -> 2018066.1
A14: Type 1 - 1200 mm | B14: 9.5 - 10.0 | C14: =IFERROR(VLOOKUP($A14,'Manhole Rate'!$A$1:$AC$4,MATCH($B14,'Manhole Rate'!$B$1:$AC$1,0)+1,0),"N/F") -> 6679.0581 | D14: 252 | E14: 235 | F14: 252 | G14: 252 | H14: 252 | I14: 252 | J14: 252 | K14: =IFERROR(D14*$C14,0) -> 1683122.6 | L14: =IFERROR(E14*$C14,0) -> 1569578.6 | M14: =IFERROR(F14*$C14,0) -> 1683122.6 | N14: =IFERROR(G14*$C14,0) -> 1683122.6 | O14: =IFERROR(H14*$C14,0) -> 1683122.6 | P14: =IFERROR(I14*$C14,0) -> 1683122.6 | Q14: =IFERROR(J14*$C14,0) -> 1683122.6
... A19: Type 1 - 1200 mm | B19: 14.5 - 15.0 | C19: =IFERROR(VLOOKUP($A19,'Manhole Rate'!$A$1:$AC$4,MATCH($B19,'Manhole Rate'!$B$1:$AC$1,0)+1,0),"N/F") -> 22210.86 | D19: 9 | E19: 9 | F19: 9 | G19: 9 | H19: 9 | I19: 9 | J19: 9 | K19: =IFERROR(D19*$C19,0) -> 199897.74 | L19: =IFERROR(E19*$C19,0) -> 199897.74 | M19: =IFERROR(F19*$C19,0) -> 199897.74 | N19: =IFERROR(G19*$C19,0) -> 199897.74 | O19: =IFERROR(H19*$C19,0) -> 199897.74 | P19: =IFERROR(I19*$C19,0) -> 199897.74 | Q19: =IFERROR(J19*$C19,0) -> 199897.74
A20: Type 2 - 1500 mm | B20: 2.0 - 2.5 | C20: =IFERROR(VLOOKUP($A20,'Manhole Rate'!$A$1:$AC$4,MATCH($B20,'Manhole Rate'!$B$1:$AC$1,0)+1,0),"N/F") -> 1102.9759 | D20: 9 | E20: 9 | F20: 12 | G20: 12 | J20: 9 | K20: =IFERROR(D20*$C20,0) -> 9926.7833 | L20: =IFERROR(E20*$C20,0) -> 9926.7833 | M20: =IFERROR(F20*$C20,0) -> 13235.711 | N20: =IFERROR(G20*$C20,0) -> 13235.711 | O20: =IFERROR(H20*$C20,0) -> 0 | P20: =IFERROR(I20*$C20,0) -> 0 | Q20: =IFERROR(J20*$C20,0) -> 9926.7833
A21: Type 2 - 1500 mm | B21: 2.5 - 3.0 | C21: =IFERROR(VLOOKUP($A21,'Manhole Rate'!$A$1:$AC$4,MATCH($B21,'Manhole Rate'!$B$1:$AC$1,0)+1,0),"N/F") -> 1224.3033 | D21: 47 | E21: 47 | F21: 42 | G21: 28 | H21: 8 | I21: 8 | J21: 47 | K21: =IFERROR(D21*$C21,0) -> 57542.254 | L21: =IFERROR(E21*$C21,0) -> 57542.254 | M21: =IFERROR(F21*$C21,0) -> 51420.737 | N21: =IFERROR(G21*$C21,0) -> 34280.492 | O21: =IFERROR(H21*$C21,0) -> 9794.4262 | P21: =IFERROR(I21*$C21,0) -> 9794.4262 | Q21: =IFERROR(J21*$C21,0) -> 57542.254
A22: Type 2 - 1500 mm | B22: 3.0 - 3.5 | C22: =IFERROR(VLOOKUP($A22,'Manhole Rate'!$A$1:$AC$4,MATCH($B22,'Manhole Rate'!$B$1:$AC$1,0)+1,0),"N/F") -> 1358.9766 | D22: 32 | E22: 32 | F22: 23 | G22: 17 | H22: 7 | I22: 7 | J22: 32 | K22: =IFERROR(D22*$C22,0) -> 43487.252 | L22: =IFERROR(E22*$C22,0) -> 43487.252 | M22: =IFERROR(F22*$C22,0) -> 31256.463 | N22: =IFERROR(G22*$C22,0) -> 23102.603 | O22: =IFERROR(H22*$C22,0) -> 9512.8364 | P22: =IFERROR(I22*$C22,0) -> 9512.8364 | Q22: =IFERROR(J22*$C22,0) -> 43487.252
A23: Type 2 - 1500 mm | B23: 3.5 - 4.0 | C23: =IFERROR(VLOOKUP($A23,'Manhole Rate'!$A$1:$AC$4,MATCH($B23,'Manhole Rate'!$B$1:$AC$1,0)+1,0),"N/F") -> 1508.4641 | D23: 22 | E23: 22 | F23: 17 | G23: 12 | H23: 7 | I23: 7 | J23: 22 | K23: =IFERROR(D23*$C23,0) -> 33186.209 | L23: =IFERROR(E23*$C23,0) -> 33186.209 | M23: =IFERROR(F23*$C23,0) -> 25643.889 | N23: =IFERROR(G23*$C23,0) -> 18101.569 | O23: =IFERROR(H23*$C23,0) -> 10559.248 | P23: =IFERROR(I23*$C23,0) -> 10559.248 | Q23: =IFERROR(J23*$C23,0) -> 33186.209
A24: Type 2 - 1500 mm | B24: 4.5 - 5.0 | C24: =IFERROR(VLOOKUP($A24,'Manhole Rate'!$A$1:$AC$4,MATCH($B24,'Manhole Rate'!$B$1:$AC$1,0)+1,0),"N/F") -> 1858.5786 | D24: 69 | E24: 69 | F24: 51 | G24: 24 | H24: 19 | I24: 19 | J24: 69 | K24: =IFERROR(D24*$C24,0) -> 128241.92 | L24: =IFERROR(E24*$C24,0) -> 128241.92 | M24: =IFERROR(F24*$C24,0) -> 94787.507 | N24: =IFERROR(G24*$C24,0) -> 44605.886 | O24: =IFERROR(H24*$C24,0) -> 35312.993 | P24: =IFERROR(I24*$C24,0) -> 35312.993 | Q24: =IFERROR(J24*$C24,0) -> 128241.92
A25: Type 2 - 1500 mm | B25: 5.5 - 6.0 | C25: =IFERROR(VLOOKUP($A25,'Manhole Rate'!$A$1:$AC$4,MATCH($B25,'Manhole Rate'!$B$1:$AC$1,0)+1,0),"N/F") -> 2289.9547 | D25: 48 | E25: 48 | F25: 42 | G25: 25 | H25: 23 | I25: 23 | J25: 48 | K25: =IFERROR(D25*$C25,0) -> 109917.82 | L25: =IFERROR(E25*$C25,0) -> 109917.82 | M25: =IFERROR(F25*$C25,0) -> 96178.095 | N25: =IFERROR(G25*$C25,0) -> 57248.866 | O25: =IFERROR(H25*$C25,0) -> 52668.957 | P25: =IFERROR(I25*$C25,0) -> 52668.957 | Q25: =IFERROR(J25*$C25,0) -> 109917.82
A26: Type 2 - 1500 mm | B26: 6.5 - 7.0 | C26: =IFERROR(VLOOKUP($A26,'Manhole Rate'!$A$1:$AC$4,MATCH($B26,'Manhole Rate'!$B$1:$AC$1,0)+1,0),"N/F") -> 3304.4046 | D26: 45 | E26: 45 | F26: 59 | G26: 40 | H26: 30 | I26: 30 | J26: 45 | K26: =IFERROR(D26*$C26,0) -> 148698.21 | L26: =IFERROR(E26*$C26,0) -> 148698.21 | M26: =IFERROR(F26*$C26,0) -> 194959.87 | N26: =IFERROR(G26*$C26,0) -> 132176.18 | O26: =IFERROR(H26*$C26,0) -> 99132.137 | P26: =IFERROR(I26*$C26,0) -> 99132.137 | Q26: =IFERROR(J26*$C26,0) -> 148698.21
A27: Type 2 - 1500 mm | B27: 7.5 - 8.0 | C27: =IFERROR(VLOOKUP($A27,'Manhole Rate'!$A$1:$AC$4,MATCH($B27,'Manhole Rate'!$B$1:$AC$1,0)+1,0),"N/F") -> 4071.3569 | D27: 41 | E27: 41 | F27: 51 | G27: 37 | H27: 26 | I27: 25 | J27: 40 | K27: =IFERROR(D27*$C27,0) -> 166925.63 | L27: =IFERROR(E27*$C27,0) -> 166925.63 | M27: =IFERROR(F27*$C27,0) -> 207639.2 | N27: =IFERROR(G27*$C27,0) -> 150640.2 | O27: =IFERROR(H27*$C27,0) -> 105855.28 | P27: =IFERROR(I27*$C27,0) -> 101783.92 | Q27: =IFERROR(J27*$C27,0) -> 162854.27
A28: Type 2 - 1500 mm | B28: 8.5 - 9.0 | C28: =IFERROR(VLOOKUP($A28,'Manhole Rate'!$A$1:$AC$4,MATCH($B28,'Manhole Rate'!$B$1:$AC$1,0)+1,0),"N/F") -> 5016.3188 | D28: 23 | E28: 23 | F28: 25 | G28: 25 | H28: 24 | I28: 24 | J28: 23 | K28: =IFERROR(D28*$C28,0) -> 115375.33 | L28: =IFERROR(E28*$C28,0) -> 115375.33 | M28: =IFERROR(F28*$C28,0) -> 125407.97 | N28: =IFERROR(G28*$C28,0) -> 125407.97 | O28: =IFERROR(H28*$C28,0) -> 120391.65 | P28: =IFERROR(I28*$C28,0) -> 120391.65 | Q28: =IFERROR(J28*$C28,0) -> 115375.33
A29: Type 2 - 1500 mm | B29: 9.5 - 10.0 | C29: =IFERROR(VLOOKUP($A29,'Manhole Rate'!$A$1:$AC$4,MATCH($B29,'Manhole Rate'!$B$1:$AC$1,0)+1,0),"N/F") -> 7238.548 | D29: 20 | E29: 20 | F29: 23 | G29: 23 | H29: 33 | I29: 33 | J29: 20 | K29: =IFERROR(D29*$C29,0) -> 144770.96 | L29: =IFERROR(E29*$C29,0) -> 144770.96 | M29: =IFERROR(F29*$C29,0) -> 166486.6 | N29: =IFERROR(G29*$C29,0) -> 166486.6 | O29: =IFERROR(H29*$C29,0) -> 238872.08 | P29: =IFERROR(I29*$C29,0) -> 238872.08 | Q29: =IFERROR(J29*$C29,0) -> 144770.96
