Workbook
Name demand_comb: 'Water Demand Criteria'!$B$26
Name headroom_percentile: 'Water Demand Criteria'!$E$21
Name outage_range: #REF!
Name use_outage: 'Water Demand Criteria'!$E$22

Sheet Pop_Wilayat
D2: Raw data from NCSI : Forecast Omani (21-40) + Forecast Expats (21-40) | X2: Extrapolation : Omani (41-50) + Expats (41-50) [cf Technical Note on Population]
A3: Gov_Code | B3: Wilayat_Code | C3: Name | D3: 2021 | E3: 2022 | F3: 2023 | G3: 2024 | H3: 2025 | I3: 2026 | J3: 2027 | K3: 2028 | L3: 2029 | M3: 2030 | N3: 2031 | O3: 2032 | P3: 2033 | Q3: 2034 | R3: 2035 | S3: 2036 | T3: 2037 | U3: 2038 | V3: 2039 | W3: 2040 | X3: 2041 | Y3: 2042 | Z3: 2043 | AA3: 2044 | AB3: 2045 | AC3: 2046 | AD3: 2047 | AE3: 2048 | AF3: 2049 | AG3: 2050
A4: 10 | B4: 1001 | C4: IBRI | D4: 168409 | E4: 173418 | F4: 178477 | G4: 183564 | H4: 187962 | I4: 193116 | J4: 198344 | K4: 203659 | L4: 209063 | M4: 213637 | N4: 219186 | O4: 224840 | P4: 227736 | Q4: 236531 | R4: 241464 | S4: 247702 | T4: 254186 | U4: 260898 | V4: 267898 | W4: 273725 | X4: 278946.71 | Y4: 284406.82 | Z4: 290036.9 | AA4: 295848.66 | AB4: 301853.79 | AC4: 308064 | AD4: 314490.97 | AE4: 321146.41 | AF4: 328042.01 | AG4: 335189.48
C6: TOTAL Population | D6: =SUM(D4:D4) -> 168409 | E6: =SUM(E4:E4) -> 173418 | F6: =SUM(F4:F4) -> 178477 | G6: =SUM(G4:G4) -> 183564 | H6: =SUM(H4:H4) -> 187962 | I6: =SUM(I4:I4) -> 193116 | J6: =SUM(J4:J4) -> 198344 | K6: =SUM(K4:K4) -> 203659 | ... AG6: =SUM(AG4:AG4) -> 335189.48
B7: Code | C7: Name | D7: 2021 | E7: 2022 | F7: 2023 | G7: 2024 | H7: 2025 | I7: 2026 | J7: 2027 | K7: 2028 | L7: 2029 | M7: 2030 | N7: 2031 | O7: 2032 | P7: 2033 | Q7: 2034 | R7: 2035 | S7: 2036 | T7: 2037 | U7: 2038 | V7: 2039 | W7: 2040 | X7: 2041 | Y7: 2042 | Z7: 2043 | AA7: 2044 | AB7: 2045 | AC7: 2046 | AD7: 2047 | AE7: 2048 | AF7: 2049 | AG7: 2050 | AH7: 2051 | AI7: 2052 | AJ7: 2053 | AK7: 2054 | AL7: 2055 | AM7: 2056 | AN7: 2057 | AO7: 2058 | AP7: 2059 | AQ7: 2060 | AR7: 2061 | AS7: 2062 | AT7: 2063 | AU7: 2064 | AV7: 2065 | AW7: 2066 | AX7: 2067 | AY7: 2068 | AZ7: 2069 | BA7: 2070 | BB7: 2071 | BC7: 2072 | BD7: 2073 | BE7: 2074 | BF7: 2075 | BG7: 2076 | BH7: 2077 | BI7: 2078 | BJ7: 2079 | BK7: 2080 | BL7: 2081 | BM7: 2082 | BN7: 2083 | BO7: 2084 | BP7: 2085 | BQ7: 2086 | BR7: 2087 | BS7: 2088 | BT7: 2089 | BU7: 2090 | BV7: 2091 | BW7: 2092 | BX7: 2093 | BY7: 2094 | BZ7: 2095 | CA7: 2096 | CB7: 2097 | CC7: 2098 | CD7: 2099 | CE7: 2100
B8: 10 | C8: Adh Dhahirah | D8: =SUMIF($A$4:$A$4,$B8,D$4:D$4) -> 168409 | E8: =SUMIF($A$4:$A$4,$B8,E$4:E$4) -> 173418 | F8: =SUMIF($A$4:$A$4,$B8,F$4:F$4) -> 178477 | G8: =SUMIF($A$4:$A$4,$B8,G$4:G$4) -> 183564 | H8: =SUMIF($A$4:$A$4,$B8,H$4:H$4) -> 187962 | I8: =SUMIF($A$4:$A$4,$B8,I$4:I$4) -> 193116 | J8: =SUMIF($A$4:$A$4,$B8,J$4:J$4) -> 198344 | K8: =SUMIF($A$4:$A$4,$B8,K$4:K$4) -> 203659 | ... AG8: =SUMIF($A$4:$A$4,$B8,AG$4:AG$4) -> 335189.48
B10: Growth Rate | C10: Ibri | E10: =(E4/D4)-1 -> 0.029743066 | F10: =(F4/E4)-1 -> 0.029172289 | G10: =(G4/F4)-1 -> 0.028502272 | H10: =(H4/G4)-1 -> 0.023958946 | I10: =(I4/H4)-1 -> 0.027420436 | J10: =(J4/I4)-1 -> 0.027071812 | K10: =(K4/J4)-1 -> 0.026796878 | L10: =(L4/K4)-1 -> 0.02653455 | ... AG10: =(AG4/AF4)-1 -> 0.021788262 | AH10: =AG10+0.0003 -> 0.022088262 | AI10: =AH10+0.0003 -> 0.022388262 | AJ10: =AI10+0.0003 -> 0.022688262 | AK10: =AJ10+0.0003 -> 0.022988262 | AL10: =AK10+0.0003 -> 0.023288262 | AM10: =AL10+0.0003 -> 0.023588262 | AN10: =AM10+0.0003 -> 0.023888262 | AO10: 0.024 | AP10: 0.024 | AQ10: 0.024 | AR10: 0.024 | AS10: 0.024 | AT10: 0.024 | AU10: 0.024 | AV10: 0.024 | AW10: 0.024 | AX10: 0.024 | AY10: 0.024 | AZ10: 0.024 | BA10: 0.024 | BB10: 0.024 | BC10: 0.024 | BD10: 0.024 | BE10: 0.024 | BF10: 0.024 | BG10: 0.024 | BH10: 0.024 | BI10: 0.024 | BJ10: 0.024 | BK10: 0.024 | BL10: 0.024 | BM10: 0.024 | BN10: 0.024 | BO10: 0.024 | BP10: 0.024 | BQ10: 0.024 | BR10: 0.024 | BS10: 0.024 | BT10: 0.024 | BU10: 0.024 | BV10: 0.024 | BW10: 0.024 | BX10: 0.024 | BY10: 0.024 | BZ10: 0.024 | CA10: 0.024 | CB10: 0.024 | CC10: 0.024 | CD10: 0.024 | CE10: 0.024
B11: W_Pop_Connected | D11: 0.46677996 | E11: 0.48807003 | F11: 0.49257275 | G11: 0.50546915 | H11: 0.53224468 | I11: 0.55902021 | J11: 0.58579574 | K11: 0.61257128 | L11: 0.63934681 | M11: 0.66612234 | N11: 0.69289787 | O11: 0.7196734 | P11: 0.74644894 | Q11: 0.77322447 | R11: 0.8 | S11: 0.8 | T11: 0.8 | U11: 0.8 | V11: 0.8 | W11: 0.8 | X11: 0.8 | Y11: 0.8 | Z11: 0.8 | AA11: 0.8 | AB11: 0.8 | AC11: 0.8 | AD11: 0.8 | AE11: 0.8 | AF11: 0.8 | AG11: 0.8 | AH11: 0.81 | AI11: 0.82 | AJ11: 0.83 | AK11: 0.84 | AL11: 0.85 | AM11: 0.86 | AN11: 0.87 | AO11: 0.88 | AP11: 0.89 | AQ11: 0.9 | AR11: 0.91 | AS11: 0.92 | AT11: 0.93 | AU11: 0.94 | AV11: 0.95 | AW11: 0.96 | AX11: 0.97 | AY11: 0.98 | AZ11: 0.99 | BA11: 1 | BB11: 1 | BC11: 1 | BD11: 1 | BE11: 1 | BF11: 1 | BG11: 1 | BH11: 1 | BI11: 1 | BJ11: 1 | BK11: 1 | BL11: 1 | BM11: 1 | BN11: 1 | BO11: 1 | BP11: 1 | BQ11: 1 | BR11: 1 | BS11: 1 | BT11: 1 | BU11: 1 | BV11: 1 | BW11: 1 | BX11: 1 | BY11: 1 | BZ11: 1 | CA11: 1 | CB11: 1 | CC11: 1 | CD11: 1 | CE11: 1

Sheet Ibri Pop Settlements
A1: WILLAYAT | B1: Wilayah | C1: WSZ | D1: Governorate | E1: TOWN_CODE | F1: Ratio Settl/Gov | G1: Ratio Settl/Wilayat | H1: NAMEEN | I1: 2023 | J1: 2024 | K1: 2025 | L1: 2026 | M1: 2027 | N1: 2028 | O1: 2029 | P1: 2030 | Q1: 2031 | R1: 2032 | S1: 2033 | T1: 2034 | U1: 2035 | V1: 2036 | W1: 2037 | X1: 2038 | Y1: 2039 | Z1: 2040 | AA1: 2041 | AB1: 2042 | AC1: 2043 | AD1: 2044 | AE1: 2045 | AF1: 2046 | AG1: 2047 | AH1: 2048 | AI1: 2049 | AJ1: 2050
A2: 1001 | B2: IBRI | C2: WSZ 13 | D2: Adh Dhahirah | E2: 100110555 | F2: 0.0010146708 | G2: 0.0013226361 | H2: ABU DHIKRI | I2: 236.06013 | J2: 242.78838 | K2: 248.60533 | L2: 255.4222 | M2: 262.33694 | N2: 269.36675 | O2: 276.51428 | P2: 282.56401 | Q2: 289.90332 | R2: 297.38151 | S2: 301.21186 | T2: 312.84445 | U2: 319.36901 | V2: 327.61961 | W2: 336.19559 | X2: 345.07312 | Y2: 354.33157 | Z2: 362.03857 | AA2: 368.945 | AB2: 376.16673 | AC2: 383.61328 | AD2: 391.30013 | AE2: 399.24273 | AF2: 407.45657 | AG2: 415.95712 | AH2: 424.75984 | AI2: 433.88022 | AJ2: 443.33371
A3: 1001 | B3: IBRI | C3: WSZ 13 | D3: Adh Dhahirah | E3: 100140402 | F3: 4.5931602e-05 | G3: 5.9872417e-05 | H3: ABU KHABI | I3: 10.685849 | J3: 10.99042 | K3: 11.253739 | L3: 11.562322 | M3: 11.875335 | N3: 12.193557 | O3: 12.517107 | P3: 12.790964 | Q3: 13.123196 | R3: 13.461714 | S3: 13.635105 | T3: 14.161683 | U3: 14.457033 | V3: 14.830518 | W3: 15.21873 | X3: 15.620594 | Y3: 16.039701 | Z3: 16.388577 | AA3: 16.701214 | AB3: 17.028124 | AC3: 17.36521 | AD3: 17.713174 | AE3: 18.072716 | AF3: 18.444536 | AG3: 18.829335 | AH3: 19.227812 | AI3: 19.640668 | AJ3: 20.068604
A4: 1001 | B4: IBRI | C4: WSZ 13 | D4: Adh Dhahirah | E4: 100120640 | F4: 0.00018372641 | G4: 0.00023948967 | H4: ABU MILI | I4: 42.743398 | J4: 43.961682 | K4: 45.014957 | L4: 46.249287 | M4: 47.501339 | N4: 48.774227 | O4: 50.068429 | P4: 51.163854 | Q4: 52.492783 | R4: 53.846857 | S4: 54.540419 | T4: 56.646731 | U4: 57.828134 | V4: 59.32207 | W4: 60.874921 | X4: 62.482376 | Y4: 64.158803 | Z4: 65.55431 | AA4: 66.804856 | AB4: 68.112495 | AC4: 69.460841 | AD4: 70.852698 | AE4: 72.290865 | AF4: 73.778145 | AG4: 75.317338 | AH4: 76.911247 | AI4: 78.562673 | AJ4: 80.274417
A5: 1001 | B5: IBRI | C5: WSZ 13 | D5: Adh Dhahirah | E5: 100110153 | F5: 0.049522618 | G5: 0.064553352 | H5: AD DARIZ | I5: 11521.289 | J5: 11849.671 | K5: 12133.577 | L5: 12466.285 | M5: 12803.77 | N5: 13146.871 | O5: 13495.717 | P5: 13790.984 | Q5: 14149.191 | R5: 14514.176 | S5: 14701.122 | T5: 15268.869 | U5: 15587.311 | V5: 15989.994 | W5: 16408.558 | X5: 16841.84 | Y5: 17293.714 | Z5: 17669.866 | AA5: 18006.945 | AB5: 18359.413 | AC5: 18722.854 | AD5: 19098.023 | AE5: 19485.674 | AF5: 19886.564 | AG5: 20301.446 | AH5: 20731.077 | AI5: 21176.211 | AJ5: 21637.604
A6: 1001 | B6: IBRI | C6: WSZ 13 | D6: Adh Dhahirah | E6: 100130080 | F6: 0.010075723 | G6: 0.013133831 | H6: AD DIBAYSHI | I6: 2344.0868 | J6: 2410.8986 | K6: 2468.6612 | L6: 2536.3529 | M6: 2605.0166 | N6: 2674.8229 | O6: 2745.7981 | P6: 2805.8723 | Q6: 2878.7519 | R6: 2953.0106 | S6: 2991.0462 | T6: 3106.5582 | U6: 3171.3474 | V6: 3253.2763 | W6: 3338.436 | X6: 3426.5903 | Y6: 3518.5271 | Z6: 3595.0579 | AA6: 3663.639 | AB6: 3735.3511 | AC6: 3809.2957 | AD6: 3885.6264 | AE6: 3964.4968 | AF6: 4046.0605 | AG6: 4130.4713 | AH6: 4217.8827 | AI6: 4308.4484 | AJ6: 4402.322
A7: 1001 | B7: IBRI | C7: WSZ 13 | D7: Adh Dhahirah | E7: 100120383 | F7: 0.00066809603 | G7: 0.00087087152 | H7: AD DISHAH | I7: 155.43054 | J7: 159.86066 | K7: 163.69075 | L7: 168.17923 | M7: 172.73214 | N7: 177.36082 | O7: 182.06701 | P7: 186.05038 | Q7: 190.88285 | R7: 195.80675 | S7: 198.3288 | T7: 205.98811 | U7: 210.28412 | V7: 215.71662 | W7: 221.36335 | X7: 227.20864 | Y7: 233.30474 | Z7: 238.37931 | AA7: 242.92675 | AB7: 247.6818 | AC7: 252.58488 | AD7: 257.64617 | AE7: 262.87587 | AF7: 268.28416 | AG7: 273.88123 | AH7: 279.67726 | AI7: 285.68245 | AJ7: 291.90697
A8: 1001 | B8: IBRI | C8: WSZ 13 | D8: Adh Dhahirah | E8: 100120401 | F8: 0.003353007 | G8: 0.0043706865 | H8: AL ABLAH | I8: 780.06701 | J8: 802.30069 | K8: 821.52297 | L8: 844.04949 | M8: 866.89944 | N8: 890.12963 | O8: 913.74882 | P8: 933.74034 | Q8: 957.99328 | R8: 982.70514 | S8: 995.36265 | T8: 1033.8028 | U8: 1055.3634 | V8: 1082.6278 | W8: 1110.9673 | X8: 1140.3034 | Y8: 1170.8982 | Z8: 1196.3662 | AA8: 1219.1886 | AB8: 1243.053 | AC8: 1267.6604 | AD8: 1293.0617 | AE8: 1319.3083 | AF8: 1346.4511 | AG8: 1374.5414 | AH8: 1403.6303 | AI8: 1433.7688 | AJ8: 1465.0081
A9: 1001 | B9: IBRI | C9: WSZ 13 | D9: Adh Dhahirah | E9: 100140422 | F9: 0.00087270044 | G9: 0.0011375759 | H9: AL AFLAJ | I9: 203.03114 | J9: 208.81799 | K9: 213.82105 | L9: 219.68411 | M9: 225.63136 | N9: 231.67758 | O9: 237.82504 | P9: 243.02831 | Q9: 249.34072 | R9: 255.77257 | S9: 259.06699 | T9: 269.07197 | U9: 274.68363 | V9: 281.77983 | W9: 289.15588 | X9: 296.79128 | Y9: 304.75432 | Z9: 311.38297 | AA9: 317.32307 | AB9: 323.53435 | AC9: 329.939 | AD9: 336.55031 | AE9: 343.38161 | AF9: 350.44619 | AG9: 357.75736 | AH9: 365.32843 | AI9: 373.1727 | AJ9: 381.30348
A10: 1001 | B10: IBRI | C10: WSZ 13 | D10: Adh Dhahirah | E10: 100120440 | F10: 0.00077248603 | G10: 0.0010069452 | H10: AL AJUZ | I10: 179.71656 | J10: 184.83889 | K10: 189.26743 | L10: 194.45723 | M10: 199.72154 | N10: 205.07345 | O10: 210.51498 | P10: 215.12075 | Q10: 220.70829 | R10: 226.40156 | S10: 229.31767 | T10: 238.17376 | U10: 243.14102 | V10: 249.42234 | W10: 255.95137 | X10: 262.70999 | Y10: 269.75861 | Z10: 275.62607 | AA10: 280.88405 | AB10: 286.38208 | AC10: 292.05127 | AD10: 297.90339 | AE10: 303.95023 | AF10: 310.20356 | AG10: 316.67517 | AH10: 323.37684 | AI10: 330.32033 | AJ10: 337.51744
A11: 1001 | B11: IBRI | C11: WSZ 13 | D11: Adh Dhahirah | E11: 100140030 | F11: 0.00082676884 | G11: 0.0010777035 | H11: AL AKHEEDAR | I11: 192.34529 | J11: 197.82757 | K11: 202.56731 | L11: 208.12179 | M11: 213.75603 | N11: 219.48402 | O11: 225.30793 | P11: 230.23735 | Q11: 236.21752 | R11: 242.31086 | S11: 245.43189 | T11: 254.91029 | U11: 260.2266 | V11: 266.94932 | W11: 273.93714 | X11: 281.17069 | Y11: 288.71462 | Z11: 294.99439 | AA11: 300.62185 | AB11: 306.50623 | AC11: 312.57379 | AD11: 318.83714 | AE11: 325.30889 | AF11: 332.00165 | AG11: 338.92802 | AH11: 346.10061 | AI11: 353.53203 | AJ11: 361.23488
A12: 1001 | B12: IBRI | C12: WSZ 13 | D12: Adh Dhahirah | E12: 100110081 | F12: 0.0446998 | G12: 0.058266748 | H12: AL ARAQI | I12: 10399.274 | J12: 10695.677 | K12: 10951.934 | L12: 11252.241 | M12: 11556.86 | N12: 11866.548 | O12: 12181.421 | P12: 12447.933 | Q12: 12771.255 | R12: 13100.696 | S12: 13269.436 | T12: 13781.892 | U12: 14069.322 | V12: 14432.79 | W12: 14810.592 | X12: 15201.678 | Y12: 15609.545 | Z12: 15949.066 | AA12: 16253.318 | AB12: 16571.46 | AC12: 16899.507 | AD12: 17238.139 | AE12: 17588.039 | AF12: 17949.887 | AG12: 18324.366 | AH12: 18712.157 | AI12: 19113.941 | AJ12: 19530.401
A13: 1001 | B13: IBRI | C13: WSZ 13 | D13: Adh Dhahirah | E13: 100110280 | F13: 0.015892334 | G13: 0.020715856 | H13: AL ARID | I13: 3697.3039 | J13: 3802.6855 | K13: 3893.7938 | L13: 4000.5633 | M13: 4108.8658 | N13: 4218.9706 | O13: 4330.9191 | P13: 4425.6734 | Q13: 4540.6257 | R13: 4657.7532 | S13: 4717.7463 | T13: 4899.9422 | U13: 5002.1335 | V13: 5131.3591 | W13: 5265.6807 | X13: 5404.7255 | Y13: 5549.7365 | Z13: 5670.4478 | AA13: 5778.62 | AB13: 5891.7308 | AC13: 6008.3628 | AD13: 6128.7584 | AE13: 6253.1598 | AF13: 6381.8095 | AG13: 6514.9498 | AH13: 6652.8229 | AI13: 6795.6712 | AJ13: 6943.7371
... A240: 1001 | B240: IBRI | C240: WSZ 13 | D240: Adh Dhahirah | E240: 100110486 | F240: 0.00044261362 | G240: 0.00057695239 | H240: WADI YABT | I240: 102.97273 | J240: 105.90769 | K240: 108.44512 | L240: 111.41874 | M240: 114.43504 | N240: 117.50155 | O240: 120.6194 | P240: 123.25838 | Q240: 126.45989 | R240: 129.72197 | S240: 131.39283 | T240: 136.46712 | U240: 139.31323 | V240: 142.91226 | W240: 146.65322 | X240: 150.52572 | Y240: 154.56439 | Z240: 157.92629 | AA240: 160.93897 | AB240: 164.08919 | AC240: 167.33748 | AD240: 170.69059 | AE240: 174.15527 | AF240: 177.73826 | AG240: 181.44632 | AH240: 185.28619 | AI240: 189.26462 | AJ240: 193.38837

Sheet Ibri Tankers
A1: Governorate | B1: Wilayah | C1: Water Supply Zone | D1: Settlement | E1: Settlement Code | F1: TOWN_CODE | G1: 2024 | H1: 2025 | I1: 2026 | J1: 2027 | K1: 2028 | L1: 2029 | M1: 2030 | N1: 2031 | O1: 2032 | P1: 2033 | Q1: 2034 | R1: 2035 | S1: 2036 | T1: 2037 | U1: 2038 | V1: 2039 | W1: 2040 | X1: 2041 | Y1: 2042 | Z1: 2043 | AA1: 2044 | AB1: 2045 | AC1: 2046 | AD1: 2047 | AE1: 2048 | AF1: 2049 | AG1: 2050
A2: Adh Dhahirah | B2: IBRI | C2: WSZ 13 | D2: ABU DHIKRI | E2: 1001 | F2: 100110555 | G2: 5.2204803 | H2: 5.2204803 | I2: 5.2204803 | J2: 5.2204803 | K2: 5.2204803 | L2: 5.2204803 | M2: 5.2204803 | N2: 5.2204803 | O2: 5.2204803 | P2: 5.2204803 | Q2: 5.2204803 | R2: 5.2204803 | S2: 5.2204803 | T2: 5.2204803 | U2: 5.2204803 | V2: 5.2204803 | W2: 5.2204803 | X2: 5.2204803 | Y2: 5.2204803 | Z2: 5.2204803 | AA2: 5.2204803 | AB2: 5.2204803 | AC2: 5.2204803 | AD2: 5.2204803 | AE2: 5.2204803 | AF2: 5.2204803 | AG2: 5.2204803
A3: Adh Dhahirah | B3: IBRI | C3: WSZ 13 | D3: ABU KHABI | E3: 1001 | F3: 100140402 | G3: 0.23631804 | H3: 0.23631804 | I3: 0.23631804 | J3: 0.23631804 | K3: 0.23631804 | L3: 0.23631804 | M3: 0.23631804 | N3: 0.23631804 | O3: 0.23631804 | P3: 0.23631804 | Q3: 0.23631804 | R3: 0.23631804 | S3: 0.23631804 | T3: 0.23631804 | U3: 0.23631804 | V3: 0.23631804 | W3: 0.23631804 | X3: 0.23631804 | Y3: 0.23631804 | Z3: 0.23631804 | AA3: 0.23631804 | AB3: 0.23631804 | AC3: 0.23631804 | AD3: 0.23631804 | AE3: 0.23631804 | AF3: 0.23631804 | AG3: 0.23631804
A4: Adh Dhahirah | B4: IBRI | C4: WSZ 13 | D4: ABU MILI | E4: 1001 | F4: 100120640 | G4: 0.94527215 | H4: 0.94527215 | I4: 0.94527215 | J4: 0.94527215 | K4: 0.94527215 | L4: 0.94527215 | M4: 0.94527215 | N4: 0.94527215 | O4: 0.94527215 | P4: 0.94527215 | Q4: 0.94527215 | R4: 0.94527215 | S4: 0.94527215 | T4: 0.94527215 | U4: 0.94527215 | V4: 0.94527215 | W4: 0.94527215 | X4: 0.94527215 | Y4: 0.94527215 | Z4: 0.94527215 | AA4: 0.94527215 | AB4: 0.94527215 | AC4: 0.94527215 | AD4: 0.94527215 | AE4: 0.94527215 | AF4: 0.94527215 | AG4: 0.94527215
A5: Adh Dhahirah | B5: IBRI | C5: WSZ 13 | D5: AD DARIZ | E5: 1001 | F5: 100110153 | G5: 254.79381 | H5: 254.79381 | I5: 254.79381 | J5: 254.79381 | K5: 254.79381 | L5: 254.79381 | M5: 254.79381 | N5: 254.79381 | O5: 254.79381 | P5: 254.79381 | Q5: 254.79381 | R5: 254.79381 | S5: 254.79381 | T5: 254.79381 | U5: 254.79381 | V5: 254.79381 | W5: 254.79381 | X5: 254.79381 | Y5: 254.79381 | Z5: 254.79381 | AA5: 254.79381 | AB5: 254.79381 | AC5: 254.79381 | AD5: 254.79381 | AE5: 254.79381 | AF5: 254.79381 | AG5: 254.79381
A6: Adh Dhahirah | B6: IBRI | C6: WSZ 13 | D6: AD DIBAYSHI | E6: 1001 | F6: 100130080 | G6: 51.839584 | H6: 51.839584 | I6: 51.839584 | J6: 51.839584 | K6: 51.839584 | L6: 51.839584 | M6: 51.839584 | N6: 51.839584 | O6: 51.839584 | P6: 51.839584 | Q6: 51.839584 | R6: 51.839584 | S6: 51.839584 | T6: 51.839584 | U6: 51.839584 | V6: 51.839584 | W6: 51.839584 | X6: 51.839584 | Y6: 51.839584 | Z6: 51.839584 | AA6: 51.839584 | AB6: 51.839584 | AC6: 51.839584 | AD6: 51.839584 | AE6: 51.839584 | AF6: 51.839584 | AG6: 51.839584
A7: Adh Dhahirah | B7: IBRI | C7: WSZ 13 | D7: AD DISHAH | E7: 1001 | F7: 100120383 | G7: 3.4373533 | H7: 3.4373533 | I7: 3.4373533 | J7: 3.4373533 | K7: 3.4373533 | L7: 3.4373533 | M7: 3.4373533 | N7: 3.4373533 | O7: 3.4373533 | P7: 3.4373533 | Q7: 3.4373533 | R7: 3.4373533 | S7: 3.4373533 | T7: 3.4373533 | U7: 3.4373533 | V7: 3.4373533 | W7: 3.4373533 | X7: 3.4373533 | Y7: 3.4373533 | Z7: 3.4373533 | AA7: 3.4373533 | AB7: 3.4373533 | AC7: 3.4373533 | AD7: 3.4373533 | AE7: 3.4373533 | AF7: 3.4373533 | AG7: 3.4373533
A8: Adh Dhahirah | B8: IBRI | C8: WSZ 13 | D8: AL ABLAH | E8: 1001 | F8: 100120401 | G8: 17.251217 | H8: 17.251217 | I8: 17.251217 | J8: 17.251217 | K8: 17.251217 | L8: 17.251217 | M8: 17.251217 | N8: 17.251217 | O8: 17.251217 | P8: 17.251217 | Q8: 17.251217 | R8: 17.251217 | S8: 17.251217 | T8: 17.251217 | U8: 17.251217 | V8: 17.251217 | W8: 17.251217 | X8: 17.251217 | Y8: 17.251217 | Z8: 17.251217 | AA8: 17.251217 | AB8: 17.251217 | AC8: 17.251217 | AD8: 17.251217 | AE8: 17.251217 | AF8: 17.251217 | AG8: 17.251217
A9: Adh Dhahirah | B9: IBRI | C9: WSZ 13 | D9: AL AFLAJ | E9: 1001 | F9: 100140422 | G9: 4.4900427 | H9: 4.4900427 | I9: 4.4900427 | J9: 4.4900427 | K9: 4.4900427 | L9: 4.4900427 | M9: 4.4900427 | N9: 4.4900427 | O9: 4.4900427 | P9: 4.4900427 | Q9: 4.4900427 | R9: 4.4900427 | S9: 4.4900427 | T9: 4.4900427 | U9: 4.4900427 | V9: 4.4900427 | W9: 4.4900427 | X9: 4.4900427 | Y9: 4.4900427 | Z9: 4.4900427 | AA9: 4.4900427 | AB9: 4.4900427 | AC9: 4.4900427 | AD9: 4.4900427 | AE9: 4.4900427 | AF9: 4.4900427 | AG9: 4.4900427
A10: Adh Dhahirah | B10: IBRI | C10: WSZ 13 | D10: AL AJUZ | E10: 1001 | F10: 100120440 | G10: 3.9744397 | H10: 3.9744397 | I10: 3.9744397 | J10: 3.9744397 | K10: 3.9744397 | L10: 3.9744397 | M10: 3.9744397 | N10: 3.9744397 | O10: 3.9744397 | P10: 3.9744397 | Q10: 3.9744397 | R10: 3.9744397 | S10: 3.9744397 | T10: 3.9744397 | U10: 3.9744397 | V10: 3.9744397 | W10: 3.9744397 | X10: 3.9744397 | Y10: 3.9744397 | Z10: 3.9744397 | AA10: 3.9744397 | AB10: 3.9744397 | AC10: 3.9744397 | AD10: 3.9744397 | AE10: 3.9744397 | AF10: 3.9744397 | AG10: 3.9744397
A11: Adh Dhahirah | B11: IBRI | C11: WSZ 13 | D11: AL AKHEEDAR | E11: 1001 | F11: 100140030 | G11: 4.2537247 | H11: 4.2537247 | I11: 4.2537247 | J11: 4.2537247 | K11: 4.2537247 | L11: 4.2537247 | M11: 4.2537247 | N11: 4.2537247 | O11: 4.2537247 | P11: 4.2537247 | Q11: 4.2537247 | R11: 4.2537247 | S11: 4.2537247 | T11: 4.2537247 | U11: 4.2537247 | V11: 4.2537247 | W11: 4.2537247 | X11: 4.2537247 | Y11: 4.2537247 | Z11: 4.2537247 | AA11: 4.2537247 | AB11: 4.2537247 | AC11: 4.2537247 | AD11: 4.2537247 | AE11: 4.2537247 | AF11: 4.2537247 | AG11: 4.2537247
A12: Adh Dhahirah | B12: IBRI | C12: WSZ 13 | D12: AL ARAQI | E12: 1001 | F12: 100110081 | G12: 229.98042 | H12: 229.98042 | I12: 229.98042 | J12: 229.98042 | K12: 229.98042 | L12: 229.98042 | M12: 229.98042 | N12: 229.98042 | O12: 229.98042 | P12: 229.98042 | Q12: 229.98042 | R12: 229.98042 | S12: 229.98042 | T12: 229.98042 | U12: 229.98042 | V12: 229.98042 | W12: 229.98042 | X12: 229.98042 | Y12: 229.98042 | Z12: 229.98042 | AA12: 229.98042 | AB12: 229.98042 | AC12: 229.98042 | AD12: 229.98042 | AE12: 229.98042 | AF12: 229.98042 | AG12: 229.98042
... A240: Adh Dhahirah | B240: IBRI | C240: WSZ 13 | D240: WADI YABT | E240: 1001 | F240: 100110486 | G240: 2.2772465 | H240: 2.2772465 | I240: 2.2772465 | J240: 2.2772465 | K240: 2.2772465 | L240: 2.2772465 | M240: 2.2772465 | N240: 2.2772465 | O240: 2.2772465 | P240: 2.2772465 | Q240: 2.2772465 | R240: 2.2772465 | S240: 2.2772465 | T240: 2.2772465 | U240: 2.2772465 | V240: 2.2772465 | W240: 2.2772465 | X240: 2.2772465 | Y240: 2.2772465 | Z240: 2.2772465 | AA240: 2.2772465 | AB240: 2.2772465 | AC240: 2.2772465 | AD240: 2.2772465 | AE240: 2.2772465 | AF240: 2.2772465 | AG240: 2.2772465

Sheet Water Demand Criteria
B1: Water Demand Criteria - Assumptions & Calculation
B5: LPCD Calculation & Projection [Liter/capita/day] | E5: 2021 - 2023 : Annual Consumption / [365 * Customer * OR * 1000]
E6: 2024 - 2050 : Average (2021 - 2023) ==> [Fixed in Time]
B8: Gov_Code | C8: Governorate | D8: 2021 | E8: 2022 | F8: 2023 | G8: 2024 | H8: 2025 | I8: 2026 | J8: 2027 | K8: 2028 | L8: 2029 | M8: 2030 | N8: 2031 | O8: 2032 | P8: 2033 | Q8: 2034 | R8: 2035 | S8: 2036 | T8: 2037 | U8: 2038 | V8: 2039 | W8: 2040 | X8: 2041 | Y8: 2042 | Z8: 2043 | AA8: 2044 | AB8: 2045 | AC8: 2046 | AD8: 2047 | AE8: 2048 | AF8: 2049 | AG8: 2050 | AH8: 2051 | AI8: 2052 | AJ8: 2053 | AK8: 2054 | AL8: 2055 | AM8: 2056 | AN8: 2057 | AO8: 2058 | AP8: 2059 | AQ8: 2060 | AR8: 2061 | AS8: 2062 | AT8: 2063 | AU8: 2064 | AV8: 2065 | AW8: 2066 | AX8: 2067 | AY8: 2068 | AZ8: 2069 | BA8: 2070 | BB8: 2071 | BC8: 2072 | BD8: 2073 | BE8: 2074 | BF8: 2075 | BG8: 2076 | BH8: 2077 | BI8: 2078 | BJ8: 2079 | BK8: 2080 | BL8: 2081 | BM8: 2082 | BN8: 2083 | BO8: 2084 | BP8: 2085 | BQ8: 2086 | BR8: 2087 | BS8: 2088 | BT8: 2089 | BU8: 2090 | BV8: 2091 | BW8: 2092 | BX8: 2093 | BY8: 2094 | BZ8: 2095 | CA8: 2096 | CB8: 2097 | CC8: 2098 | CD8: 2099 | CE8: 2100
B9: 01 | C9: Muscat | D9: =VLOOKUP($C9,[1]NWS_Input!$B$8:$E$18,D$20,FALSE)*1000/(365*VLOOKUP($C9,[1]NWS_Input!$B$51:$E$61,D$20,FALSE)*VLOOKUP($C9,[1]Pop_Wilayat!$B$78:$F$88,D$21,FALSE)) -> 175.81948 | E9: =VLOOKUP($C9,[1]NWS_Input!$B$8:$E$18,E$20,FALSE)*1000/(365*VLOOKUP($C9,[1]NWS_Input!$B$51:$E$61,E$20,FALSE)*VLOOKUP($C9,[1]Pop_Wilayat!$B$78:$F$88,E$21,FALSE)) -> 162.06864 | F9: =VLOOKUP($C9,[1]NWS_Input!$B$8:$E$18,F$20,FALSE)*1000/(365*VLOOKUP($C9,[1]NWS_Input!$B$51:$E$61,F$20,FALSE)*VLOOKUP($C9,[1]Pop_Wilayat!$B$78:$F$88,F$21,FALSE)) -> 160.26268 | G9: =AVERAGE(D9:F9) -> 166.05027 | H9: =G9 -> 166.05027 | I9: =H9 -> 166.05027 | J9: =I9 -> 166.05027 | K9: =J9 -> 166.05027 | L9: =K9 -> 166.05027 | M9: =L9 -> 166.05027 | N9: =M9 -> 166.05027 | O9: =N9 -> 166.05027 | ... AG9: =AF9 -> 166.05027
B10: 03 | C10: Musandam | D10: =VLOOKUP($C10,[1]NWS_Input!$B$8:$E$18,D$20,FALSE)*1000/(365*VLOOKUP($C10,[1]NWS_Input!$B$51:$E$61,D$20,FALSE)*VLOOKUP($C10,[1]Pop_Wilayat!$B$78:$F$88,D$21,FALSE)) -> 193.50184 | E10: =VLOOKUP($C10,[1]NWS_Input!$B$8:$E$18,E$20,FALSE)*1000/(365*VLOOKUP($C10,[1]NWS_Input!$B$51:$E$61,E$20,FALSE)*VLOOKUP($C10,[1]Pop_Wilayat!$B$78:$F$88,E$21,FALSE)) -> 146.85954 | F10: =VLOOKUP($C10,[1]NWS_Input!$B$8:$E$18,F$20,FALSE)*1000/(365*VLOOKUP($C10,[1]NWS_Input!$B$51:$E$61,F$20,FALSE)*VLOOKUP($C10,[1]Pop_Wilayat!$B$78:$F$88,F$21,FALSE)) -> 141.90375 | G10: =AVERAGE(D10:F10) -> 160.75505 | H10: =G10 -> 160.75505 | I10: =H10 -> 160.75505 | J10: =I10 -> 160.75505 | K10: =J10 -> 160.75505 | L10: =K10 -> 160.75505 | M10: =L10 -> 160.75505 | N10: =M10 -> 160.75505 | O10: =N10 -> 160.75505 | ... AG10: =AF10 -> 160.75505
B11: 04 | C11: Al Buraymi | D11: =VLOOKUP($C11,[1]NWS_Input!$B$8:$E$18,D$20,FALSE)*1000/(365*VLOOKUP($C11,[1]NWS_Input!$B$51:$E$61,D$20,FALSE)*VLOOKUP($C11,[1]Pop_Wilayat!$B$78:$F$88,D$21,FALSE)) -> 180.74378 | E11: =VLOOKUP($C11,[1]NWS_Input!$B$8:$E$18,E$20,FALSE)*1000/(365*VLOOKUP($C11,[1]NWS_Input!$B$51:$E$61,E$20,FALSE)*VLOOKUP($C11,[1]Pop_Wilayat!$B$78:$F$88,E$21,FALSE)) -> 144.31389 | F11: =VLOOKUP($C11,[1]NWS_Input!$B$8:$E$18,F$20,FALSE)*1000/(365*VLOOKUP($C11,[1]NWS_Input!$B$51:$E$61,F$20,FALSE)*VLOOKUP($C11,[1]Pop_Wilayat!$B$78:$F$88,F$21,FALSE)) -> 133.15838 | G11: =AVERAGE(D11:F11) -> 152.73868 | H11: =G11 -> 152.73868 | I11: =H11 -> 152.73868 | J11: =I11 -> 152.73868 | K11: =J11 -> 152.73868 | L11: =K11 -> 152.73868 | M11: =L11 -> 152.73868 | N11: =M11 -> 152.73868 | O11: =N11 -> 152.73868 | ... AG11: =AF11 -> 152.73868
B12: 05 | C12: Ad Dakhliyah | D12: =VLOOKUP($C12,[1]NWS_Input!$B$8:$E$18,D$20,FALSE)*1000/(365*VLOOKUP($C12,[1]NWS_Input!$B$51:$E$61,D$20,FALSE)*VLOOKUP($C12,[1]Pop_Wilayat!$B$78:$F$88,D$21,FALSE)) -> 206.72793 | E12: =VLOOKUP($C12,[1]NWS_Input!$B$8:$E$18,E$20,FALSE)*1000/(365*VLOOKUP($C12,[1]NWS_Input!$B$51:$E$61,E$20,FALSE)*VLOOKUP($C12,[1]Pop_Wilayat!$B$78:$F$88,E$21,FALSE)) -> 152.54485 | F12: =VLOOKUP($C12,[1]NWS_Input!$B$8:$E$18,F$20,FALSE)*1000/(365*VLOOKUP($C12,[1]NWS_Input!$B$51:$E$61,F$20,FALSE)*VLOOKUP($C12,[1]Pop_Wilayat!$B$78:$F$88,F$21,FALSE)) -> 137.49567 | G12: =AVERAGE(D12:F12) -> 165.58948 | H12: =G12 -> 165.58948 | I12: =H12 -> 165.58948 | J12: =I12 -> 165.58948 | K12: =J12 -> 165.58948 | L12: =K12 -> 165.58948 | M12: =L12 -> 165.58948 | N12: =M12 -> 165.58948 | O12: =N12 -> 165.58948 | ... AG12: =AF12 -> 165.58948
B13: 06 | C13: Al Batinah North | D13: =VLOOKUP($C13,[1]NWS_Input!$B$8:$E$18,D$20,FALSE)*1000/(365*VLOOKUP($C13,[1]NWS_Input!$B$51:$E$61,D$20,FALSE)*VLOOKUP($C13,[1]Pop_Wilayat!$B$78:$F$88,D$21,FALSE)) -> 169.4819 | E13: =VLOOKUP($C13,[1]NWS_Input!$B$8:$E$18,E$20,FALSE)*1000/(365*VLOOKUP($C13,[1]NWS_Input!$B$51:$E$61,E$20,FALSE)*VLOOKUP($C13,[1]Pop_Wilayat!$B$78:$F$88,E$21,FALSE)) -> 131.28275 | F13: =VLOOKUP($C13,[1]NWS_Input!$B$8:$E$18,F$20,FALSE)*1000/(365*VLOOKUP($C13,[1]NWS_Input!$B$51:$E$61,F$20,FALSE)*VLOOKUP($C13,[1]Pop_Wilayat!$B$78:$F$88,F$21,FALSE)) -> 117.53423 | G13: =AVERAGE(D13:F13) -> 139.43296 | H13: =G13 -> 139.43296 | I13: =H13 -> 139.43296 | J13: =I13 -> 139.43296 | K13: =J13 -> 139.43296 | L13: =K13 -> 139.43296 | M13: =L13 -> 139.43296 | N13: =M13 -> 139.43296 | O13: =N13 -> 139.43296 | ... AG13: =AF13 -> 139.43296
B14: 07 | C14: Al Batinah South | D14: =VLOOKUP($C14,[1]NWS_Input!$B$8:$E$18,D$20,FALSE)*1000/(365*VLOOKUP($C14,[1]NWS_Input!$B$51:$E$61,D$20,FALSE)*VLOOKUP($C14,[1]Pop_Wilayat!$B$78:$F$88,D$21,FALSE)) -> 189.54685 | E14: =VLOOKUP($C14,[1]NWS_Input!$B$8:$E$18,E$20,FALSE)*1000/(365*VLOOKUP($C14,[1]NWS_Input!$B$51:$E$61,E$20,FALSE)*VLOOKUP($C14,[1]Pop_Wilayat!$B$78:$F$88,E$21,FALSE)) -> 153.43673 | F14: =VLOOKUP($C14,[1]NWS_Input!$B$8:$E$18,F$20,FALSE)*1000/(365*VLOOKUP($C14,[1]NWS_Input!$B$51:$E$61,F$20,FALSE)*VLOOKUP($C14,[1]Pop_Wilayat!$B$78:$F$88,F$21,FALSE)) -> 143.18782 | G14: =AVERAGE(D14:F14) -> 162.05713 | H14: =G14 -> 162.05713 | I14: =H14 -> 162.05713 | J14: =I14 -> 162.05713 | K14: =J14 -> 162.05713 | L14: =K14 -> 162.05713 | M14: =L14 -> 162.05713 | N14: =M14 -> 162.05713 | O14: =N14 -> 162.05713 | ... AG14: =AF14 -> 162.05713
B15: 08 | C15: Ash Sharqiyah South | D15: =VLOOKUP($C15,[1]NWS_Input!$B$8:$E$18,D$20,FALSE)*1000/(365*VLOOKUP($C15,[1]NWS_Input!$B$51:$E$61,D$20,FALSE)*VLOOKUP($C15,[1]Pop_Wilayat!$B$78:$F$88,D$21,FALSE)) -> 176.00376 | E15: =VLOOKUP($C15,[1]NWS_Input!$B$8:$E$18,E$20,FALSE)*1000/(365*VLOOKUP($C15,[1]NWS_Input!$B$51:$E$61,E$20,FALSE)*VLOOKUP($C15,[1]Pop_Wilayat!$B$78:$F$88,E$21,FALSE)) -> 126.9688 | F15: =VLOOKUP($C15,[1]NWS_Input!$B$8:$E$18,F$20,FALSE)*1000/(365*VLOOKUP($C15,[1]NWS_Input!$B$51:$E$61,F$20,FALSE)*VLOOKUP($C15,[1]Pop_Wilayat!$B$78:$F$88,F$21,FALSE)) -> 117.10352 | G15: =AVERAGE(D15:F15) -> 140.02536 | H15: =G15 -> 140.02536 | I15: =H15 -> 140.02536 | J15: =I15 -> 140.02536 | K15: =J15 -> 140.02536 | L15: =K15 -> 140.02536 | M15: =L15 -> 140.02536 | N15: =M15 -> 140.02536 | O15: =N15 -> 140.02536 | ... AG15: =AF15 -> 140.02536
B16: 09 | C16: Ash Sharqiyah North | D16: =VLOOKUP($C16,[1]NWS_Input!$B$8:$E$18,D$20,FALSE)*1000/(365*VLOOKUP($C16,[1]NWS_Input!$B$51:$E$61,D$20,FALSE)*VLOOKUP($C16,[1]Pop_Wilayat!$B$78:$F$88,D$21,FALSE)) -> 197.70454 | E16: =VLOOKUP($C16,[1]NWS_Input!$B$8:$E$18,E$20,FALSE)*1000/(365*VLOOKUP($C16,[1]NWS_Input!$B$51:$E$61,E$20,FALSE)*VLOOKUP($C16,[1]Pop_Wilayat!$B$78:$F$88,E$21,FALSE)) -> 133.30537 | F16: =VLOOKUP($C16,[1]NWS_Input!$B$8:$E$18,F$20,FALSE)*1000/(365*VLOOKUP($C16,[1]NWS_Input!$B$51:$E$61,F$20,FALSE)*VLOOKUP($C16,[1]Pop_Wilayat!$B$78:$F$88,F$21,FALSE)) -> 124.26047 | G16: =AVERAGE(D16:F16) -> 151.75679 | H16: =G16 -> 151.75679 | I16: =H16 -> 151.75679 | J16: =I16 -> 151.75679 | K16: =J16 -> 151.75679 | L16: =K16 -> 151.75679 | M16: =L16 -> 151.75679 | N16: =M16 -> 151.75679 | O16: =N16 -> 151.75679 | ... AG16: =AF16 -> 151.75679
B17: 10 | C17: Adh Dhahirah | D17: =VLOOKUP($C17,[1]NWS_Input!$B$8:$E$18,D$20,FALSE)*1000/(365*VLOOKUP($C17,[1]NWS_Input!$B$51:$E$61,D$20,FALSE)*VLOOKUP($C17,[1]Pop_Wilayat!$B$78:$F$88,D$21,FALSE)) -> 196.9621 | E17: =VLOOKUP($C17,[1]NWS_Input!$B$8:$E$18,E$20,FALSE)*1000/(365*VLOOKUP($C17,[1]NWS_Input!$B$51:$E$61,E$20,FALSE)*VLOOKUP($C17,[1]Pop_Wilayat!$B$78:$F$88,E$21,FALSE)) -> 149.42231 | F17: =VLOOKUP($C17,[1]NWS_Input!$B$8:$E$18,F$20,FALSE)*1000/(365*VLOOKUP($C17,[1]NWS_Input!$B$51:$E$61,F$20,FALSE)*VLOOKUP($C17,[1]Pop_Wilayat!$B$78:$F$88,F$21,FALSE)) -> 144.11747 | G17: =AVERAGE(D17:F17) -> 163.50063 | H17: =G17 -> 163.50063 | I17: =H17 -> 163.50063 | J17: =I17 -> 163.50063 | K17: =J17 -> 163.50063 | L17: =K17 -> 163.50063 | M17: =L17 -> 163.50063 | N17: =M17 -> 163.50063 | O17: =N17 -> 163.50063 | ... CE17: =CD17 -> 163.50063
B18: 11 | C18: Al Wusta | D18: =VLOOKUP($C18,[1]NWS_Input!$B$8:$E$18,D$20,FALSE)*1000/(365*VLOOKUP($C18,[1]NWS_Input!$B$51:$E$61,D$20,FALSE)*VLOOKUP($C18,[1]Pop_Wilayat!$B$78:$F$88,D$21,FALSE)) -> 135.9262 | E18: =VLOOKUP($C18,[1]NWS_Input!$B$8:$E$18,E$20,FALSE)*1000/(365*VLOOKUP($C18,[1]NWS_Input!$B$51:$E$61,E$20,FALSE)*VLOOKUP($C18,[1]Pop_Wilayat!$B$78:$F$88,E$21,FALSE)) -> 95.96117 | F18: =VLOOKUP($C18,[1]NWS_Input!$B$8:$E$18,F$20,FALSE)*1000/(365*VLOOKUP($C18,[1]NWS_Input!$B$51:$E$61,F$20,FALSE)*VLOOKUP($C18,[1]Pop_Wilayat!$B$78:$F$88,F$21,FALSE)) -> 111.23499 | G18: =AVERAGE(D18:F18) -> 114.37412 | H18: =G18 -> 114.37412 | I18: =H18 -> 114.37412 | J18: =I18 -> 114.37412 | K18: =J18 -> 114.37412 | L18: =K18 -> 114.37412 | M18: =L18 -> 114.37412 | N18: =M18 -> 114.37412 | O18: =N18 -> 114.37412 | ... AG18: =AF18 -> 114.37412
C19: TOTAL NWS | D19: =VLOOKUP($C19,[1]NWS_Input!$B$8:$E$18,D$20,FALSE)*1000/(365*VLOOKUP($C19,[1]NWS_Input!$B$51:$E$61,D$20,FALSE)*VLOOKUP($C19,[1]Pop_Wilayat!$B$78:$F$88,D$21,FALSE)) -> 180.39114 | E19: =VLOOKUP($C19,[1]NWS_Input!$B$8:$E$18,E$20,FALSE)*1000/(365*VLOOKUP($C19,[1]NWS_Input!$B$51:$E$61,E$20,FALSE)*VLOOKUP($C19,[1]Pop_Wilayat!$B$78:$F$88,E$21,FALSE)) -> 148.17405 | F19: =VLOOKUP($C19,[1]NWS_Input!$B$8:$E$18,F$20,FALSE)*1000/(365*VLOOKUP($C19,[1]NWS_Input!$B$51:$E$61,F$20,FALSE)*VLOOKUP($C19,[1]Pop_Wilayat!$B$78:$F$88,F$21,FALSE)) -> 140.58637 | G19: =AVERAGE(D19:F19) -> 156.38385 | H19: =G19 -> 156.38385 | I19: =H19 -> 156.38385 | J19: =I19 -> 156.38385 | K19: =J19 -> 156.38385 | L19: =K19 -> 156.38385 | M19: =L19 -> 156.38385 | N19: =M19 -> 156.38385 | O19: =N19 -> 156.38385 | ... AG19: =AF19 -> 156.38385
C20: INDEX Annual Consumption & Customer | D20: 2 | E20: 3 | F20: 4 | G20: 5 | H20: 6 | I20: 7 | J20: 8 | K20: 9 | L20: 10 | M20: 11 | N20: 12 | O20: 13 | P20: 14 | Q20: 15 | R20: 16 | S20: 17 | T20: 18 | U20: 19 | V20: 20 | W20: 21 | X20: 22 | Y20: 23 | Z20: 24 | AA20: 25 | AB20: 26 | AC20: 27 | AD20: 28 | AE20: 29 | AF20: 30 | AG20: 31
C21: INDEX - Occupancy Rate | D21: 3 | E21: 4 | F21: 5 | G21: 6 | H21: 7 | I21: 8 | J21: 9 | K21: 10 | L21: 11 | M21: 12 | N21: 13 | O21: 14 | P21: 15 | Q21: 16 | R21: 17 | S21: 18 | T21: 19 | U21: 20 | V21: 21 | W21: 22 | X21: 23 | Y21: 24 | Z21: 25 | AA21: 26 | AB21: 27 | AC21: 28 | AD21: 29 | AE21: 30 | AF21: 31 | AG21: 32
B25: Governmental Ratio | E25: 2022-2023 : Gov consumption(year) / Dom consumption(year) | M25: (Al Wusta is calculated only on 2023 because of negative data in 2022)
E26: 2024 : ∑Gov consumption(22-23) / ∑Dom consumption(22-23) | M26: 2025 - 2050 : [Fixed in Time]
B28: Gov_Code | C28: Governorate | D28: 2021 | E28: 2022 | F28: 2023 | G28: 2024 | H28: 2025 | I28: 2026 | J28: 2027 | K28: 2028 | L28: 2029 | M28: 2030 | N28: 2031 | O28: 2032 | P28: 2033 | Q28: 2034 | R28: 2035 | S28: 2036 | T28: 2037 | U28: 2038 | V28: 2039 | W28: 2040 | X28: 2041 | Y28: 2042 | Z28: 2043 | AA28: 2044 | AB28: 2045 | AC28: 2046 | AD28: 2047 | AE28: 2048 | AF28: 2049 | AG28: 2050 | AH28: 2051 | AI28: 2052 | AJ28: 2053 | AK28: 2054 | AL28: 2055 | AM28: 2056 | AN28: 2057 | AO28: 2058 | AP28: 2059 | AQ28: 2060 | AR28: 2061 | AS28: 2062 | AT28: 2063 | AU28: 2064 | AV28: 2065 | AW28: 2066 | AX28: 2067 | AY28: 2068 | AZ28: 2069 | BA28: 2070 | BB28: 2071 | BC28: 2072 | BD28: 2073 | BE28: 2074 | BF28: 2075 | BG28: 2076 | BH28: 2077 | BI28: 2078 | BJ28: 2079 | BK28: 2080 | BL28: 2081 | BM28: 2082 | BN28: 2083 | BO28: 2084 | BP28: 2085 | BQ28: 2086 | BR28: 2087 | BS28: 2088 | BT28: 2089 | BU28: 2090 | BV28: 2091 | BW28: 2092 | BX28: 2093 | BY28: 2094 | BZ28: 2095 | CA28: 2096 | CB28: 2097 | CC28: 2098 | CD28: 2099 | CE28: 2100
B29: 01 | C29: Muscat | E29: =(VLOOKUP(C29,[1]NWS_Input!$B$22:$E$32,'Water Demand Criteria'!G$40,FALSE))/VLOOKUP(C29,[1]NWS_Input!$B$8:$E$18,G$40,FALSE) -> 0.37071855 | F29: =VLOOKUP(C29,[1]NWS_Input!$B$22:$E$32,'Water Demand Criteria'!H$40,FALSE)/VLOOKUP(C29,[1]NWS_Input!$B$8:$E$18,H$40,FALSE) -> 0.38505973 | G29: =(VLOOKUP(C29,[1]NWS_Input!$B$22:$E$32,'Water Demand Criteria'!G$40,FALSE)+VLOOKUP(C29,[1]NWS_Input!$B$22:$E$32,'Water Demand Criteria'!H$40,FALSE))/(VLOOKUP(C29,[1]NWS_Input!$B$8:$E$18,G$40,FALSE)+VLOOKUP(C29,[1]NWS_Input!$B$8:$E$18,H$40,FALSE)) -> 0.3780138 | H29: =G29 -> 0.3780138 | I29: =H29 -> 0.3780138 | J29: =I29 -> 0.3780138 | K29: =J29 -> 0.3780138 | L29: =K29 -> 0.3780138 | M29: =L29 -> 0.3780138 | N29: =M29 -> 0.3780138 | O29: =N29 -> 0.3780138 | ... AG29: =AF29 -> 0.3780138
B30: 03 | C30: Musandam | E30: =(VLOOKUP(C30,[1]NWS_Input!$B$22:$E$32,'Water Demand Criteria'!G$40,FALSE))/VLOOKUP(C30,[1]NWS_Input!$B$8:$E$18,G$40,FALSE) -> 0.30419387 | F30: =VLOOKUP(C30,[1]NWS_Input!$B$22:$E$32,'Water Demand Criteria'!H$40,FALSE)/VLOOKUP(C30,[1]NWS_Input!$B$8:$E$18,H$40,FALSE) -> 0.37158974 | G30: =(VLOOKUP(C30,[1]NWS_Input!$B$22:$E$32,'Water Demand Criteria'!G$40,FALSE)+VLOOKUP(C30,[1]NWS_Input!$B$22:$E$32,'Water Demand Criteria'!H$40,FALSE))/(VLOOKUP(C30,[1]NWS_Input!$B$8:$E$18,G$40,FALSE)+VLOOKUP(C30,[1]NWS_Input!$B$8:$E$18,H$40,FALSE)) -> 0.33850226 | H30: =G30 -> 0.33850226 | I30: =H30 -> 0.33850226 | J30: =I30 -> 0.33850226 | K30: =J30 -> 0.33850226 | L30: =K30 -> 0.33850226 | M30: =L30 -> 0.33850226 | N30: =M30 -> 0.33850226 | O30: =N30 -> 0.33850226 | ... AG30: =AF30 -> 0.33850226
B31: 04 | C31: Al Buraymi | E31: =(VLOOKUP(C31,[1]NWS_Input!$B$22:$E$32,'Water Demand Criteria'!G$40,FALSE))/VLOOKUP(C31,[1]NWS_Input!$B$8:$E$18,G$40,FALSE) -> 0.19459429 | F31: =VLOOKUP(C31,[1]NWS_Input!$B$22:$E$32,'Water Demand Criteria'!H$40,FALSE)/VLOOKUP(C31,[1]NWS_Input!$B$8:$E$18,H$40,FALSE) -> 0.20857725 | G31: =(VLOOKUP(C31,[1]NWS_Input!$B$22:$E$32,'Water Demand Criteria'!G$40,FALSE)+VLOOKUP(C31,[1]NWS_Input!$B$22:$E$32,'Water Demand Criteria'!H$40,FALSE))/(VLOOKUP(C31,[1]NWS_Input!$B$8:$E$18,G$40,FALSE)+VLOOKUP(C31,[1]NWS_Input!$B$8:$E$18,H$40,FALSE)) -> 0.20150375 | H31: =G31 -> 0.20150375 | I31: =H31 -> 0.20150375 | J31: =I31 -> 0.20150375 | K31: =J31 -> 0.20150375 | L31: =K31 -> 0.20150375 | M31: =L31 -> 0.20150375 | N31: =M31 -> 0.20150375 | O31: =N31 -> 0.20150375 | ... AG31: =AF31 -> 0.20150375
B32: 05 | C32: Ad Dakhliyah | E32: =(VLOOKUP(C32,[1]NWS_Input!$B$22:$E$32,'Water Demand Criteria'!G$40,FALSE))/VLOOKUP(C32,[1]NWS_Input!$B$8:$E$18,G$40,FALSE) -> 0.26638083 | F32: =VLOOKUP(C32,[1]NWS_Input!$B$22:$E$32,'Water Demand Criteria'!H$40,FALSE)/VLOOKUP(C32,[1]NWS_Input!$B$8:$E$18,H$40,FALSE) -> 0.32400428 | G32: =(VLOOKUP(C32,[1]NWS_Input!$B$22:$E$32,'Water Demand Criteria'!G$40,FALSE)+VLOOKUP(C32,[1]NWS_Input!$B$22:$E$32,'Water Demand Criteria'!H$40,FALSE))/(VLOOKUP(C32,[1]NWS_Input!$B$8:$E$18,G$40,FALSE)+VLOOKUP(C32,[1]NWS_Input!$B$8:$E$18,H$40,FALSE)) -> 0.29442367 | H32: =G32 -> 0.29442367 | I32: =H32 -> 0.29442367 | J32: =I32 -> 0.29442367 | K32: =J32 -> 0.29442367 | L32: =K32 -> 0.29442367 | M32: =L32 -> 0.29442367 | N32: =M32 -> 0.29442367 | O32: =N32 -> 0.29442367 | ... AG32: =AF32 -> 0.29442367
B33: 06 | C33: Al Batinah North | E33: =(VLOOKUP(C33,[1]NWS_Input!$B$22:$E$32,'Water Demand Criteria'!G$40,FALSE))/VLOOKUP(C33,[1]NWS_Input!$B$8:$E$18,G$40,FALSE) -> 0.11253976 | F33: =VLOOKUP(C33,[1]NWS_Input!$B$22:$E$32,'Water Demand Criteria'!H$40,FALSE)/VLOOKUP(C33,[1]NWS_Input!$B$8:$E$18,H$40,FALSE) -> 0.13392259 | G33: =(VLOOKUP(C33,[1]NWS_Input!$B$22:$E$32,'Water Demand Criteria'!G$40,FALSE)+VLOOKUP(C33,[1]NWS_Input!$B$22:$E$32,'Water Demand Criteria'!H$40,FALSE))/(VLOOKUP(C33,[1]NWS_Input!$B$8:$E$18,G$40,FALSE)+VLOOKUP(C33,[1]NWS_Input!$B$8:$E$18,H$40,FALSE)) -> 0.12283675 | H33: =G33 -> 0.12283675 | I33: =H33 -> 0.12283675 | J33: =I33 -> 0.12283675 | K33: =J33 -> 0.12283675 | L33: =K33 -> 0.12283675 | M33: =L33 -> 0.12283675 | N33: =M33 -> 0.12283675 | O33: =N33 -> 0.12283675 | ... AG33: =AF33 -> 0.12283675
B34: 07 | C34: Al Batinah South | E34: =(VLOOKUP(C34,[1]NWS_Input!$B$22:$E$32,'Water Demand Criteria'!G$40,FALSE))/VLOOKUP(C34,[1]NWS_Input!$B$8:$E$18,G$40,FALSE) -> 0.09578915 | F34: =VLOOKUP(C34,[1]NWS_Input!$B$22:$E$32,'Water Demand Criteria'!H$40,FALSE)/VLOOKUP(C34,[1]NWS_Input!$B$8:$E$18,H$40,FALSE) -> 0.10793851 | G34: =(VLOOKUP(C34,[1]NWS_Input!$B$22:$E$32,'Water Demand Criteria'!G$40,FALSE)+VLOOKUP(C34,[1]NWS_Input!$B$22:$E$32,'Water Demand Criteria'!H$40,FALSE))/(VLOOKUP(C34,[1]NWS_Input!$B$8:$E$18,G$40,FALSE)+VLOOKUP(C34,[1]NWS_Input!$B$8:$E$18,H$40,FALSE)) -> 0.10187936 | H34: =G34 -> 0.10187936 | I34: =H34 -> 0.10187936 | J34: =I34 -> 0.10187936 | K34: =J34 -> 0.10187936 | L34: =K34 -> 0.10187936 | M34: =L34 -> 0.10187936 | N34: =M34 -> 0.10187936 | O34: =N34 -> 0.10187936 | ... AG34: =AF34 -> 0.10187936
B35: 08 | C35: Ash Sharqiyah South | E35: =(VLOOKUP(C35,[1]NWS_Input!$B$22:$E$32,'Water Demand Criteria'!G$40,FALSE))/VLOOKUP(C35,[1]NWS_Input!$B$8:$E$18,G$40,FALSE) -> 0.11400225 | F35: =VLOOKUP(C35,[1]NWS_Input!$B$22:$E$32,'Water Demand Criteria'!H$40,FALSE)/VLOOKUP(C35,[1]NWS_Input!$B$8:$E$18,H$40,FALSE) -> 0.11424541 | G35: =(VLOOKUP(C35,[1]NWS_Input!$B$22:$E$32,'Water Demand Criteria'!G$40,FALSE)+VLOOKUP(C35,[1]NWS_Input!$B$22:$E$32,'Water Demand Criteria'!H$40,FALSE))/(VLOOKUP(C35,[1]NWS_Input!$B$8:$E$18,G$40,FALSE)+VLOOKUP(C35,[1]NWS_Input!$B$8:$E$18,H$40,FALSE)) -> 0.11412311 | H35: =G35 -> 0.11412311 | I35: =H35 -> 0.11412311 | J35: =I35 -> 0.11412311 | K35: =J35 -> 0.11412311 | L35: =K35 -> 0.11412311 | M35: =L35 -> 0.11412311 | N35: =M35 -> 0.11412311 | O35: =N35 -> 0.11412311 | ... AG35: =AF35 -> 0.11412311
B36: 09 | C36: Ash Sharqiyah North | E36: =(VLOOKUP(C36,[1]NWS_Input!$B$22:$E$32,'Water Demand Criteria'!G$40,FALSE))/VLOOKUP(C36,[1]NWS_Input!$B$8:$E$18,G$40,FALSE) -> 0.12663558 | F36: =VLOOKUP(C36,[1]NWS_Input!$B$22:$E$32,'Water Demand Criteria'!H$40,FALSE)/VLOOKUP(C36,[1]NWS_Input!$B$8:$E$18,H$40,FALSE) -> 0.15443678 | G36: =(VLOOKUP(C36,[1]NWS_Input!$B$22:$E$32,'Water Demand Criteria'!G$40,FALSE)+VLOOKUP(C36,[1]NWS_Input!$B$22:$E$32,'Water Demand Criteria'!H$40,FALSE))/(VLOOKUP(C36,[1]NWS_Input!$B$8:$E$18,G$40,FALSE)+VLOOKUP(C36,[1]NWS_Input!$B$8:$E$18,H$40,FALSE)) -> 0.1405812 | H36: =G36 -> 0.1405812 | I36: =H36 -> 0.1405812 | J36: =I36 -> 0.1405812 | K36: =J36 -> 0.1405812 | L36: =K36 -> 0.1405812 | M36: =L36 -> 0.1405812 | N36: =M36 -> 0.1405812 | O36: =N36 -> 0.1405812 | ... AG36: =AF36 -> 0.1405812
B37: 10 | C37: Adh Dhahirah | E37: =(VLOOKUP(C37,[1]NWS_Input!$B$22:$E$32,'Water Demand Criteria'!G$40,FALSE))/VLOOKUP(C37,[1]NWS_Input!$B$8:$E$18,G$40,FALSE) -> 0.13545223 | F37: =VLOOKUP(C37,[1]NWS_Input!$B$22:$E$32,'Water Demand Criteria'!H$40,FALSE)/VLOOKUP(C37,[1]NWS_Input!$B$8:$E$18,H$40,FALSE) -> 0.14481925 | G37: =(VLOOKUP(C37,[1]NWS_Input!$B$22:$E$32,'Water Demand Criteria'!G$40,FALSE)+VLOOKUP(C37,[1]NWS_Input!$B$22:$E$32,'Water Demand Criteria'!H$40,FALSE))/(VLOOKUP(C37,[1]NWS_Input!$B$8:$E$18,G$40,FALSE)+VLOOKUP(C37,[1]NWS_Input!$B$8:$E$18,H$40,FALSE)) -> 0.14013866 | H37: =G37 -> 0.14013866 | I37: =H37 -> 0.14013866 | J37: =I37 -> 0.14013866 | K37: =J37 -> 0.14013866 | L37: =K37 -> 0.14013866 | M37: =L37 -> 0.14013866 | N37: =M37 -> 0.14013866 | O37: =N37 -> 0.14013866 | ... CE37: =CD37 -> 0.14013866
B38: 11 | C38: Al Wusta | E38: =(VLOOKUP(C38,[1]NWS_Input!$B$22:$E$32,'Water Demand Criteria'!G$40,FALSE))/VLOOKUP(C38,[1]NWS_Input!$B$8:$E$18,G$40,FALSE) -> -0.095113148 | F38: =VLOOKUP(C38,[1]NWS_Input!$B$22:$E$32,'Water Demand Criteria'!H$40,FALSE)/VLOOKUP(C38,[1]NWS_Input!$B$8:$E$18,H$40,FALSE) -> 0.20814953 | G38: =VLOOKUP(C38,[1]NWS_Input!$B$22:$E$32,'Water Demand Criteria'!H$40,FALSE)/VLOOKUP(C38,[1]NWS_Input!$B$8:$E$18,H$40,FALSE) -> 0.20814953 | H38: =G38 -> 0.20814953 | I38: =H38 -> 0.20814953 | J38: =I38 -> 0.20814953 | K38: =J38 -> 0.20814953 | L38: =K38 -> 0.20814953 | M38: =L38 -> 0.20814953 | N38: =M38 -> 0.20814953 | O38: =N38 -> 0.20814953 | ... AG38: =AF38 -> 0.20814953
C39: TOTAL NWS | E39: =(VLOOKUP(C39,[1]NWS_Input!$B$22:$E$32,'Water Demand Criteria'!G$40,FALSE))/VLOOKUP(C39,[1]NWS_Input!$B$8:$E$18,G$40,FALSE) -> 0.24917715 | F39: =VLOOKUP(C39,[1]NWS_Input!$B$22:$E$32,'Water Demand Criteria'!H$40,FALSE)/VLOOKUP(C39,[1]NWS_Input!$B$8:$E$18,H$40,FALSE) -> 0.27259815 | G39: =(VLOOKUP(C39,[1]NWS_Input!$B$22:$E$32,'Water Demand Criteria'!G$40,FALSE)+VLOOKUP(C39,[1]NWS_Input!$B$22:$E$32,'Water Demand Criteria'!H$40,FALSE))/(VLOOKUP(C39,[1]NWS_Input!$B$8:$E$18,G$40,FALSE)+VLOOKUP(C39,[1]NWS_Input!$B$8:$E$18,H$40,FALSE)) -> 0.26088576 | H39: =G39 -> 0.26088576 | I39: =H39 -> 0.26088576 | J39: =I39 -> 0.26088576 | K39: =J39 -> 0.26088576 | L39: =K39 -> 0.26088576 | M39: =L39 -> 0.26088576 | N39: =M39 -> 0.26088576 | O39: =N39 -> 0.26088576 | ... AG39: =AF39 -> 0.26088576
C40: INDEX Dom Consumption & Gov Consumption | G40: 3 | H40: 4 | I40: 5 | J40: 6 | K40: 7 | L40: 8 | M40: 9 | N40: 10 | O40: 11 | P40: 12 | Q40: 13 | R40: 14 | S40: 15 | T40: 16 | U40: 17 | V40: 18 | W40: 19 | X40: 20 | Y40: 21 | Z40: 22 | AA40: 23 | AB40: 24 | AC40: 25 | AD40: 26 | AE40: 27 | AF40: 28 | AG40: 29
B44: Non-Domestic Ratio | E44: 2022-2023 : ND consumption(year) / Dom consumption(year) | M44: (Al Wusta is calculated only on 2023 because of negative data in 2022)
E45: 2024 : ∑ND consumption(22-23) / ∑Dom consumption(22-23) | M45: 2025 - 2050 : [Fixed in Time]
B47: Gov_Code | C47: Governorate | D47: 2021 | E47: 2022 | F47: 2023 | G47: 2024 | H47: 2025 | I47: 2026 | J47: 2027 | K47: 2028 | L47: 2029 | M47: 2030 | N47: 2031 | O47: 2032 | P47: 2033 | Q47: 2034 | R47: 2035 | S47: 2036 | T47: 2037 | U47: 2038 | V47: 2039 | W47: 2040 | X47: 2041 | Y47: 2042 | Z47: 2043 | AA47: 2044 | AB47: 2045 | AC47: 2046 | AD47: 2047 | AE47: 2048 | AF47: 2049 | AG47: 2050 | AH47: 2051 | AI47: 2052 | AJ47: 2053 | AK47: 2054 | AL47: 2055 | AM47: 2056 | AN47: 2057 | AO47: 2058 | AP47: 2059 | AQ47: 2060 | AR47: 2061 | AS47: 2062 | AT47: 2063 | AU47: 2064 | AV47: 2065 | AW47: 2066 | AX47: 2067 | AY47: 2068 | AZ47: 2069 | BA47: 2070 | BB47: 2071 | BC47: 2072 | BD47: 2073 | BE47: 2074 | BF47: 2075 | BG47: 2076 | BH47: 2077 | BI47: 2078 | BJ47: 2079 | BK47: 2080 | BL47: 2081 | BM47: 2082 | BN47: 2083 | BO47: 2084 | BP47: 2085 | BQ47: 2086 | BR47: 2087 | BS47: 2088 | BT47: 2089 | BU47: 2090 | BV47: 2091 | BW47: 2092 | BX47: 2093 | BY47: 2094 | BZ47: 2095 | CA47: 2096 | CB47: 2097 | CC47: 2098 | CD47: 2099 | CE47: 2100
B48: 01 | C48: Muscat | E48: =VLOOKUP(C48,[1]NWS_Input!$B$36:$E$46,G$59,FALSE)/VLOOKUP(C48,[1]NWS_Input!$B$8:$E$18,G$59,FALSE) -> 0.22296673 | F48: =VLOOKUP(C48,[1]NWS_Input!$B$36:$E$46,'Water Demand Criteria'!H$59,FALSE)/VLOOKUP(C48,[1]NWS_Input!$B$8:$E$18,H$59,FALSE) -> 0.2325532 | G48: =(VLOOKUP(C48,[1]NWS_Input!$B$36:$E$46,G$59,FALSE)+VLOOKUP(C48,[1]NWS_Input!$B$36:$E$46,'Water Demand Criteria'!H$59,FALSE))/(VLOOKUP(C48,[1]NWS_Input!$B$8:$E$18,G$59,FALSE)+VLOOKUP(C48,[1]NWS_Input!$B$8:$E$18,H$59,FALSE)) -> 0.22784329 | H48: =G48 -> 0.22784329 | I48: =H48 -> 0.22784329 | J48: =I48 -> 0.22784329 | K48: =J48 -> 0.22784329 | L48: =K48 -> 0.22784329 | M48: =L48 -> 0.22784329 | N48: =M48 -> 0.22784329 | O48: =N48 -> 0.22784329 | ... AG48: =AF48 -> 0.22784329
B49: 03 | C49: Musandam | E49: =VLOOKUP(C49,[1]NWS_Input!$B$36:$E$46,G$59,FALSE)/VLOOKUP(C49,[1]NWS_Input!$B$8:$E$18,G$59,FALSE) -> 0.13991413 | F49: =VLOOKUP(C49,[1]NWS_Input!$B$36:$E$46,'Water Demand Criteria'!H$59,FALSE)/VLOOKUP(C49,[1]NWS_Input!$B$8:$E$18,H$59,FALSE) -> 0.11650315 | G49: =(VLOOKUP(C49,[1]NWS_Input!$B$36:$E$46,G$59,FALSE)+VLOOKUP(C49,[1]NWS_Input!$B$36:$E$46,'Water Demand Criteria'!H$59,FALSE))/(VLOOKUP(C49,[1]NWS_Input!$B$8:$E$18,G$59,FALSE)+VLOOKUP(C49,[1]NWS_Input!$B$8:$E$18,H$59,FALSE)) -> 0.12799659 | H49: =G49 -> 0.12799659 | I49: =H49 -> 0.12799659 | J49: =I49 -> 0.12799659 | K49: =J49 -> 0.12799659 | L49: =K49 -> 0.12799659 | M49: =L49 -> 0.12799659 | N49: =M49 -> 0.12799659 | O49: =N49 -> 0.12799659 | ... AG49: =AF49 -> 0.12799659
B50: 04 | C50: Al Buraymi | E50: =VLOOKUP(C50,[1]NWS_Input!$B$36:$E$46,G$59,FALSE)/VLOOKUP(C50,[1]NWS_Input!$B$8:$E$18,G$59,FALSE) -> 0.16276111 | F50: =VLOOKUP(C50,[1]NWS_Input!$B$36:$E$46,'Water Demand Criteria'!H$59,FALSE)/VLOOKUP(C50,[1]NWS_Input!$B$8:$E$18,H$59,FALSE) -> 0.14473363 | G50: =(VLOOKUP(C50,[1]NWS_Input!$B$36:$E$46,G$59,FALSE)+VLOOKUP(C50,[1]NWS_Input!$B$36:$E$46,'Water Demand Criteria'!H$59,FALSE))/(VLOOKUP(C50,[1]NWS_Input!$B$8:$E$18,G$59,FALSE)+VLOOKUP(C50,[1]NWS_Input!$B$8:$E$18,H$59,FALSE)) -> 0.15385313 | H50: =G50 -> 0.15385313 | I50: =H50 -> 0.15385313 | J50: =I50 -> 0.15385313 | K50: =J50 -> 0.15385313 | L50: =K50 -> 0.15385313 | M50: =L50 -> 0.15385313 | N50: =M50 -> 0.15385313 | O50: =N50 -> 0.15385313 | ... AG50: =AF50 -> 0.15385313
B51: 05 | C51: Ad Dakhliyah | E51: =VLOOKUP(C51,[1]NWS_Input!$B$36:$E$46,G$59,FALSE)/VLOOKUP(C51,[1]NWS_Input!$B$8:$E$18,G$59,FALSE) -> 0.074175093 | F51: =VLOOKUP(C51,[1]NWS_Input!$B$36:$E$46,'Water Demand Criteria'!H$59,FALSE)/VLOOKUP(C51,[1]NWS_Input!$B$8:$E$18,H$59,FALSE) -> 0.072348984 | G51: =(VLOOKUP(C51,[1]NWS_Input!$B$36:$E$46,G$59,FALSE)+VLOOKUP(C51,[1]NWS_Input!$B$36:$E$46,'Water Demand Criteria'!H$59,FALSE))/(VLOOKUP(C51,[1]NWS_Input!$B$8:$E$18,G$59,FALSE)+VLOOKUP(C51,[1]NWS_Input!$B$8:$E$18,H$59,FALSE)) -> 0.073286405 | H51: =G51 -> 0.073286405 | I51: =H51 -> 0.073286405 | J51: =I51 -> 0.073286405 | K51: =J51 -> 0.073286405 | L51: =K51 -> 0.073286405 | M51: =L51 -> 0.073286405 | N51: =M51 -> 0.073286405 | O51: =N51 -> 0.073286405 | ... AG51: =AF51 -> 0.073286405
B52: 06 | C52: Al Batinah North | E52: =VLOOKUP(C52,[1]NWS_Input!$B$36:$E$46,G$59,FALSE)/VLOOKUP(C52,[1]NWS_Input!$B$8:$E$18,G$59,FALSE) -> 0.31030895 | F52: =VLOOKUP(C52,[1]NWS_Input!$B$36:$E$46,'Water Demand Criteria'!H$59,FALSE)/VLOOKUP(C52,[1]NWS_Input!$B$8:$E$18,H$59,FALSE) -> 0.12260226 | G52: =(VLOOKUP(C52,[1]NWS_Input!$B$36:$E$46,G$59,FALSE)+VLOOKUP(C52,[1]NWS_Input!$B$36:$E$46,'Water Demand Criteria'!H$59,FALSE))/(VLOOKUP(C52,[1]NWS_Input!$B$8:$E$18,G$59,FALSE)+VLOOKUP(C52,[1]NWS_Input!$B$8:$E$18,H$59,FALSE)) -> 0.21991801 | H52: =G52 -> 0.21991801 | I52: =H52 -> 0.21991801 | J52: =I52 -> 0.21991801 | K52: =J52 -> 0.21991801 | L52: =K52 -> 0.21991801 | M52: =L52 -> 0.21991801 | N52: =M52 -> 0.21991801 | O52: =N52 -> 0.21991801 | ... AG52: =AF52 -> 0.21991801
...

Sheet Wastewater Criteria
B1: Wastewater Generation Criteria - Assumptions & Calculation
B5: Return Ratio | F5: TE Production Rate
B8: Domestic Ratio | C8: 0.85 | D8: Can be adjusted | F8: TE Production Rate
B9: Tanker Ratio | C9: 0.85 | D9: Can be adjusted | G9: 0.95 | H9: Can be adjusted
B10: Non-Domestic Ratio | C10: 0.54 | D10: Can be adjusted
B11: Governmental Ratio | C11: 0.54 | D11: Can be adjusted | F11: Sludge Production Rate
B13: Maximum Distance from STP by road
F15: Sludge rate [kg/m3]
G16: 0.25 | H16: Can be adjusted
B17: Distance (km) | C17: 25 | D17: Can be adjusted
B19: Infiltration Ratio
B23: Infiltration Ratio | C23: 0.1 | D23: Can be adjusted
B24: *Only applied to settlement with network
B27: STP Margin Security
B30: Margin coefficient | C30: 0.1 | D30: Can be adjusted
B33: Weekly Peak
B36: Weekly Peak | C36: 0.2 | D36: Can be adjusted
B42: Collection Factor | E42: Assumptions: 1 customer collected either by tanker or network produce the same amount of wastewater to the STP. If a customer is not collected by network he is collected by tanker. His flow is accounted 100% to the STP. | M42: * This factor will be impacting the wastewater generation collected by tanker, fine tuning it could allow to calibrate the wastewater generation in order to fit the actual flow treated by the STPs.
B45: Gov_Code | C45: Governorate | D45: 2021 | E45: 2022 | F45: 2023 | G45: 2024 | H45: 2025 | I45: 2026 | J45: 2027 | K45: 2028 | L45: 2029 | M45: 2030 | N45: 2031 | O45: 2032 | P45: 2033 | Q45: 2034 | R45: 2035 | S45: 2036 | T45: 2037 | U45: 2038 | V45: 2039 | W45: 2040 | X45: 2041 | Y45: 2042 | Z45: 2043 | AA45: 2044 | AB45: 2045 | AC45: 2046 | AD45: 2047 | AE45: 2048 | AF45: 2049 | AG45: 2050
B46: 01 | C46: Muscat | G46: 1 | H46: =G46 -> 1 | I46: =H46 -> 1 | J46: =I46 -> 1 | K46: =J46 -> 1 | L46: =K46 -> 1 | M46: =L46 -> 1 | N46: =M46 -> 1 | O46: =N46 -> 1 | ... AG46: =AF46 -> 1
B47: 03 | C47: Musandam | G47: 1 | H47: =G47 -> 1 | I47: =H47 -> 1 | J47: =I47 -> 1 | K47: =J47 -> 1 | L47: =K47 -> 1 | M47: =L47 -> 1 | N47: =M47 -> 1 | O47: =N47 -> 1 | ... AG47: =AF47 -> 1
B48: 04 | C48: Al Buraymi | G48: 1 | H48: =G48 -> 1 | I48: =H48 -> 1 | J48: =I48 -> 1 | K48: =J48 -> 1 | L48: =K48 -> 1 | M48: =L48 -> 1 | N48: =M48 -> 1 | O48: =N48 -> 1 | ... AG48: =AF48 -> 1
B49: 05 | C49: Ad Dakhliyah | G49: 1 | H49: =G49 -> 1 | I49: =H49 -> 1 | J49: =I49 -> 1 | K49: =J49 -> 1 | L49: =K49 -> 1 | M49: =L49 -> 1 | N49: =M49 -> 1 | O49: =N49 -> 1 | ... AG49: =AF49 -> 1
B50: 06 | C50: Al Batinah North | G50: 1 | H50: =G50 -> 1 | I50: =H50 -> 1 | J50: =I50 -> 1 | K50: =J50 -> 1 | L50: =K50 -> 1 | M50: =L50 -> 1 | N50: =M50 -> 1 | O50: =N50 -> 1 | ... AG50: =AF50 -> 1
B51: 07 | C51: Al Batinah South | G51: 1 | H51: =G51 -> 1 | I51: =H51 -> 1 | J51: =I51 -> 1 | K51: =J51 -> 1 | L51: =K51 -> 1 | M51: =L51 -> 1 | N51: =M51 -> 1 | O51: =N51 -> 1 | ... AG51: =AF51 -> 1
B52: 08 | C52: Ash Sharqiyah South | G52: 1 | H52: =G52 -> 1 | I52: =H52 -> 1 | J52: =I52 -> 1 | K52: =J52 -> 1 | L52: =K52 -> 1 | M52: =L52 -> 1 | N52: =M52 -> 1 | O52: =N52 -> 1 | ... AG52: =AF52 -> 1
B53: 09 | C53: Ash Sharqiyah North | G53: 1 | H53: =G53 -> 1 | I53: =H53 -> 1 | J53: =I53 -> 1 | K53: =J53 -> 1 | L53: =K53 -> 1 | M53: =L53 -> 1 | N53: =M53 -> 1 | O53: =N53 -> 1 | ... AG53: =AF53 -> 1
B54: 10 | C54: Adh Dhahirah | G54: 1 | H54: =G54 -> 1 | I54: =H54 -> 1 | J54: =I54 -> 1 | K54: =J54 -> 1 | L54: =K54 -> 1 | M54: =L54 -> 1 | N54: =M54 -> 1 | O54: =N54 -> 1 | ... AG54: =AF54 -> 1
B55: 11 | C55: Al Wusta | G55: 1 | H55: =G55 -> 1 | I55: =H55 -> 1 | J55: =I55 -> 1 | K55: =J55 -> 1 | L55: =K55 -> 1 | M55: =L55 -> 1 | N55: =M55 -> 1 | O55: =N55 -> 1 | ... AG55: =AF55 -> 1
C56: Total NWS | G56: 1 | H56: =G56 -> 1 | I56: =H56 -> 1 | J56: =I56 -> 1 | K56: =J56 -> 1 | L56: =K56 -> 1 | M56: =L56 -> 1 | N56: =M56 -> 1 | O56: =N56 -> 1 | ... AG56: =AF56 -> 1
B60: Footprint Assumptions
B64: Type of STPs | C64: Capacity | D64: Ratio (m²/m3/d)
B65: MBR/SBR | C65: Extension | D65: 1.1 | E65: Can be adjusted
B66: Large STPs | C66: 50000 | D66: 2 | E66: Can be adjusted
B67: Medium STPs | C67: 20000 | D67: 3.8 | E67: Can be adjusted
B68: Small STPs (<20,000) | D68: (the equation is from the graph below with empiric value from the existing STPs)
B89: Energy Assumptions
B94: MBR/SBR | C94: 1.02 | D94: kWh/m3 | E94: Can be adjusted | F94: RG MP 2018
B95: ECAS | C95: 0.82 | D95: kWh/m3 | E95: Can be adjusted | F95: RG MP 2018
B96: CAS | C96: 0.69 | D96: kWh/m3 | E96: Can be adjusted | F96: RG MP 2018
...

Sheet Project Pop Settlements
A1: No. | B1: Name | C1: Pop 2023 | D1: Pop 2024 | E1: Pop 2025 | F1: Pop 2026 | G1: Pop 2027 | H1: Pop 2028 | I1: Pop 2029 | J1: Pop 2030 | K1: Pop 2031 | L1: Pop 2032 | M1: Pop 2033 | N1: Pop 2034 | O1: Pop 2035 | P1: Pop 2036 | Q1: Pop 2037 | R1: Pop 2038 | S1: Pop 2039 | T1: Pop 2040 | U1: Pop 2041 | V1: Pop 2042 | W1: Pop 2043 | X1: Pop 2044 | Y1: Pop 2045 | Z1: Pop 2046 | AA1: Pop 2047 | AB1: Pop 2048 | AC1: Pop 2049 | AD1: Pop 2050 | AE1: Pop 2051 | AF1: Pop 2052 | AG1: Pop 2053 | AH1: Pop 2054 | AI1: Pop 2055 | AJ1: Pop 2056 | AK1: Pop 2057 | AL1: Pop 2058 | AM1: Pop 2059 | AN1: Pop 2060 | AO1: Pop 2061 | AP1: Pop 2062 | AQ1: Pop 2063 | AR1: Pop 2064 | AS1: Pop 2065 | AT1: Pop 2066 | AU1: Pop 2067 | AV1: Pop 2068 | AW1: Pop 2069 | AX1: Pop 2070 | AY1: Pop 2071 | AZ1: Pop 2072 | BA1: Pop 2073 | BB1: Pop 2074 | BC1: Pop 2075 | BD1: Pop 2076 | BE1: Pop 2077 | BF1: Pop 2078 | BG1: Pop 2079 | BH1: Pop 2080 | BI1: Pop 2081 | BJ1: Pop 2082 | BK1: Pop 2083 | BL1: Pop 2084 | BM1: Pop 2085 | BN1: Pop 2086 | BO1: Pop 2087 | BP1: Pop 2088 | BQ1: Pop 2089 | BR1: Pop 2090 | BS1: Pop 2091 | BT1: Pop 2092 | BU1: Pop 2093 | BV1: Pop 2094 | BW1: Pop 2095 | BX1: Pop 2096 | BY1: Pop 2097 | BZ1: Pop 2098 | CA1: Pop 2099 | CB1: Pop 2100
A2: 1 | B2: AD DARIZ | C2: =VLOOKUP($B2,'Ibri Pop Settlements'!$H$2:$AJ$240,C$29,FALSE) -> 11521.289 | D2: =VLOOKUP($B2,'Ibri Pop Settlements'!$H$2:$AJ$240,D$29,FALSE) -> 11849.671 | E2: =VLOOKUP($B2,'Ibri Pop Settlements'!$H$2:$AJ$240,E$29,FALSE) -> 12133.577 | F2: =VLOOKUP($B2,'Ibri Pop Settlements'!$H$2:$AJ$240,F$29,FALSE) -> 12466.285 | G2: =VLOOKUP($B2,'Ibri Pop Settlements'!$H$2:$AJ$240,G$29,FALSE) -> 12803.77 | H2: =VLOOKUP($B2,'Ibri Pop Settlements'!$H$2:$AJ$240,H$29,FALSE) -> 13146.871 | I2: =VLOOKUP($B2,'Ibri Pop Settlements'!$H$2:$AJ$240,I$29,FALSE) -> 13495.717 | J2: =VLOOKUP($B2,'Ibri Pop Settlements'!$H$2:$AJ$240,J$29,FALSE) -> 13790.984 | ... AD2: =VLOOKUP($B2,'Ibri Pop Settlements'!$H$2:$AJ$240,AD$29,FALSE) -> 21637.604 | AE2: =AD2*(1+Pop_Wilayat!AH$10) -> 22115.541 | AF2: =AE2*(1+Pop_Wilayat!AI$10) -> 22610.67 | AG2: =AF2*(1+Pop_Wilayat!AJ$10) -> 23123.667 | AH2: =AG2*(1+Pop_Wilayat!AK$10) -> 23655.24 | AI2: =AH2*(1+Pop_Wilayat!AL$10) -> 24206.129 | AJ2: =AI2*(1+Pop_Wilayat!AM$10) -> 24777.11 | AK2: =AJ2*(1+Pop_Wilayat!AN$10) -> 25368.992 | AL2: =AK2*(1+Pop_Wilayat!AO$10) -> 25977.848 | ... CB2: =CA2*(1+Pop_Wilayat!CE$10) -> 70339.835
A3: 2 | B3: AD DIBAYSHI | C3: =VLOOKUP($B3,'Ibri Pop Settlements'!$H$2:$AJ$240,C$29,FALSE) -> 2344.0868 | D3: =VLOOKUP($B3,'Ibri Pop Settlements'!$H$2:$AJ$240,D$29,FALSE) -> 2410.8986 | E3: =VLOOKUP($B3,'Ibri Pop Settlements'!$H$2:$AJ$240,E$29,FALSE) -> 2468.6612 | F3: =VLOOKUP($B3,'Ibri Pop Settlements'!$H$2:$AJ$240,F$29,FALSE) -> 2536.3529 | G3: =VLOOKUP($B3,'Ibri Pop Settlements'!$H$2:$AJ$240,G$29,FALSE) -> 2605.0166 | H3: =VLOOKUP($B3,'Ibri Pop Settlements'!$H$2:$AJ$240,H$29,FALSE) -> 2674.8229 | I3: =VLOOKUP($B3,'Ibri Pop Settlements'!$H$2:$AJ$240,I$29,FALSE) -> 2745.7981 | J3: =VLOOKUP($B3,'Ibri Pop Settlements'!$H$2:$AJ$240,J$29,FALSE) -> 2805.8723 | ... AD3: =VLOOKUP($B3,'Ibri Pop Settlements'!$H$2:$AJ$240,AD$29,FALSE) -> 4402.322 | AE3: =AD3*(1+Pop_Wilayat!AH$10) -> 4499.5617 | AF3: =AE3*(1+Pop_Wilayat!AI$10) -> 4600.299 | AG3: =AF3*(1+Pop_Wilayat!AJ$10) -> 4704.6718 | AH3: =AG3*(1+Pop_Wilayat!AK$10) -> 4812.8241 | AI3: =AH3*(1+Pop_Wilayat!AL$10) -> 4924.9064 | AJ3: =AI3*(1+Pop_Wilayat!AM$10) -> 5041.0764 | AK3: =AJ3*(1+Pop_Wilayat!AN$10) -> 5161.4989 | AL3: =AK3*(1+Pop_Wilayat!AO$10) -> 5285.3749 | ... CB3: =CA3*(1+Pop_Wilayat!CE$10) -> 14311.132
A4: 3 | B4: AL AKHEEDAR | C4: =VLOOKUP($B4,'Ibri Pop Settlements'!$H$2:$AJ$240,C$29,FALSE) -> 192.34529 | D4: =VLOOKUP($B4,'Ibri Pop Settlements'!$H$2:$AJ$240,D$29,FALSE) -> 197.82757 | E4: =VLOOKUP($B4,'Ibri Pop Settlements'!$H$2:$AJ$240,E$29,FALSE) -> 202.56731 | F4: =VLOOKUP($B4,'Ibri Pop Settlements'!$H$2:$AJ$240,F$29,FALSE) -> 208.12179 | G4: =VLOOKUP($B4,'Ibri Pop Settlements'!$H$2:$AJ$240,G$29,FALSE) -> 213.75603 | H4: =VLOOKUP($B4,'Ibri Pop Settlements'!$H$2:$AJ$240,H$29,FALSE) -> 219.48402 | I4: =VLOOKUP($B4,'Ibri Pop Settlements'!$H$2:$AJ$240,I$29,FALSE) -> 225.30793 | J4: =VLOOKUP($B4,'Ibri Pop Settlements'!$H$2:$AJ$240,J$29,FALSE) -> 230.23735 | ... AD4: =VLOOKUP($B4,'Ibri Pop Settlements'!$H$2:$AJ$240,AD$29,FALSE) -> 361.23488 | AE4: =AD4*(1+Pop_Wilayat!AH$10) -> 369.21393 | AF4: =AE4*(1+Pop_Wilayat!AI$10) -> 377.47999 | AG4: =AF4*(1+Pop_Wilayat!AJ$10) -> 386.04435 | AH4: =AG4*(1+Pop_Wilayat!AK$10) -> 394.91884 | AI4: =AH4*(1+Pop_Wilayat!AL$10) -> 404.11582 | AJ4: =AI4*(1+Pop_Wilayat!AM$10) -> 413.6482 | AK4: =AJ4*(1+Pop_Wilayat!AN$10) -> 423.52954 | AL4: =AK4*(1+Pop_Wilayat!AO$10) -> 433.69425 | ... CB4: =CA4*(1+Pop_Wilayat!CE$10) -> 1174.3075
A5: 4 | B5: AL ARAQI | C5: =VLOOKUP($B5,'Ibri Pop Settlements'!$H$2:$AJ$240,C$29,FALSE) -> 10399.274 | D5: =VLOOKUP($B5,'Ibri Pop Settlements'!$H$2:$AJ$240,D$29,FALSE) -> 10695.677 | E5: =VLOOKUP($B5,'Ibri Pop Settlements'!$H$2:$AJ$240,E$29,FALSE) -> 10951.934 | F5: =VLOOKUP($B5,'Ibri Pop Settlements'!$H$2:$AJ$240,F$29,FALSE) -> 11252.241 | G5: =VLOOKUP($B5,'Ibri Pop Settlements'!$H$2:$AJ$240,G$29,FALSE) -> 11556.86 | H5: =VLOOKUP($B5,'Ibri Pop Settlements'!$H$2:$AJ$240,H$29,FALSE) -> 11866.548 | I5: =VLOOKUP($B5,'Ibri Pop Settlements'!$H$2:$AJ$240,I$29,FALSE) -> 12181.421 | J5: =VLOOKUP($B5,'Ibri Pop Settlements'!$H$2:$AJ$240,J$29,FALSE) -> 12447.933 | ... AD5: =VLOOKUP($B5,'Ibri Pop Settlements'!$H$2:$AJ$240,AD$29,FALSE) -> 19530.401 | AE5: =AD5*(1+Pop_Wilayat!AH$10) -> 19961.794 | AF5: =AE5*(1+Pop_Wilayat!AI$10) -> 20408.703 | AG5: =AF5*(1+Pop_Wilayat!AJ$10) -> 20871.741 | AH5: =AG5*(1+Pop_Wilayat!AK$10) -> 21351.546 | AI5: =AH5*(1+Pop_Wilayat!AL$10) -> 21848.787 | AJ5: =AI5*(1+Pop_Wilayat!AM$10) -> 22364.162 | AK5: =AJ5*(1+Pop_Wilayat!AN$10) -> 22898.403 | AL5: =AK5*(1+Pop_Wilayat!AO$10) -> 23447.964 | ... CB5: =CA5*(1+Pop_Wilayat!CE$10) -> 63489.707
A6: 5 | B6: AL AYNAYN | C6: =VLOOKUP($B6,'Ibri Pop Settlements'!$H$2:$AJ$240,C$29,FALSE) -> 4427.8274 | D6: =VLOOKUP($B6,'Ibri Pop Settlements'!$H$2:$AJ$240,D$29,FALSE) -> 4554.0306 | E6: =VLOOKUP($B6,'Ibri Pop Settlements'!$H$2:$AJ$240,E$29,FALSE) -> 4663.1403 | F6: =VLOOKUP($B6,'Ibri Pop Settlements'!$H$2:$AJ$240,F$29,FALSE) -> 4791.0057 | G6: =VLOOKUP($B6,'Ibri Pop Settlements'!$H$2:$AJ$240,G$29,FALSE) -> 4920.7069 | H6: =VLOOKUP($B6,'Ibri Pop Settlements'!$H$2:$AJ$240,H$29,FALSE) -> 5052.5665 | I6: =VLOOKUP($B6,'Ibri Pop Settlements'!$H$2:$AJ$240,I$29,FALSE) -> 5186.634 | J6: =VLOOKUP($B6,'Ibri Pop Settlements'!$H$2:$AJ$240,J$29,FALSE) -> 5300.1102 | ... AD6: =VLOOKUP($B6,'Ibri Pop Settlements'!$H$2:$AJ$240,AD$29,FALSE) -> 8315.6999 | AE6: =AD6*(1+Pop_Wilayat!AH$10) -> 8499.3792 | AF6: =AE6*(1+Pop_Wilayat!AI$10) -> 8689.6656 | AG6: =AF6*(1+Pop_Wilayat!AJ$10) -> 8886.819 | AH6: =AG6*(1+Pop_Wilayat!AK$10) -> 9091.1115 | AI6: =AH6*(1+Pop_Wilayat!AL$10) -> 9302.8277 | AJ6: =AI6*(1+Pop_Wilayat!AM$10) -> 9522.2652 | AK6: =AJ6*(1+Pop_Wilayat!AN$10) -> 9749.7356 | AL6: =AK6*(1+Pop_Wilayat!AO$10) -> 9983.7293 | ... CB6: =CA6*(1+Pop_Wilayat!CE$10) -> 27032.796
A7: 6 | B7: AL GHUBAYRAH | C7: =VLOOKUP($B7,'Ibri Pop Settlements'!$H$2:$AJ$240,C$29,FALSE) -> 613.95062 | D7: =VLOOKUP($B7,'Ibri Pop Settlements'!$H$2:$AJ$240,D$29,FALSE) -> 631.44961 | E7: =VLOOKUP($B7,'Ibri Pop Settlements'!$H$2:$AJ$240,E$29,FALSE) -> 646.57848 | F7: =VLOOKUP($B7,'Ibri Pop Settlements'!$H$2:$AJ$240,F$29,FALSE) -> 664.30794 | G7: =VLOOKUP($B7,'Ibri Pop Settlements'!$H$2:$AJ$240,G$29,FALSE) -> 682.29196 | H7: =VLOOKUP($B7,'Ibri Pop Settlements'!$H$2:$AJ$240,H$29,FALSE) -> 700.57525 | I7: =VLOOKUP($B7,'Ibri Pop Settlements'!$H$2:$AJ$240,I$29,FALSE) -> 719.1647 | J7: =VLOOKUP($B7,'Ibri Pop Settlements'!$H$2:$AJ$240,J$29,FALSE) -> 734.899 | ... AD7: =VLOOKUP($B7,'Ibri Pop Settlements'!$H$2:$AJ$240,AD$29,FALSE) -> 1153.0325 | AE7: =AD7*(1+Pop_Wilayat!AH$10) -> 1178.501 | AF7: =AE7*(1+Pop_Wilayat!AI$10) -> 1204.8856 | AG7: =AF7*(1+Pop_Wilayat!AJ$10) -> 1232.2224 | AH7: =AG7*(1+Pop_Wilayat!AK$10) -> 1260.549 | AI7: =AH7*(1+Pop_Wilayat!AL$10) -> 1289.905 | AJ7: =AI7*(1+Pop_Wilayat!AM$10) -> 1320.3316 | AK7: =AJ7*(1+Pop_Wilayat!AN$10) -> 1351.8721 | AL7: =AK7*(1+Pop_Wilayat!AO$10) -> 1384.317 | ... CB7: =CA7*(1+Pop_Wilayat!CE$10) -> 3748.2947
